{
  "version": 8,
  "blockIdVersion": 11,
  "anchorX": 0,
  "anchorY": 0,
  "anchorZ": 0,
  "blocks": [
    {
      "x": -10,
      "y": 44,
      "z": -3,
      "name": "Plant_Crop_Mushroom_Block_Red",
      "rotation": 2
    },
    {
      "x": -10,
      "y": 16,
      "z": -2,
      "name": "Plant_Crop_Mushroom_Block_Red",
      "rotation": 2
    },
    {
      "x": -10,
      "y": 44,
      "z": -2,
      "name": "Plant_Crop_Mushroom_Block_Red",
      "rotation": 2
    },
    {
      "x": -10,
      "y": 53,
      "z": -2,
      "name": "Plant_Crop_Mushroom_Block_Red",
      "rotation": 2
    },
    {
      "x": -10,
      "y": 9,
      "z": -1,
      "name": "Plant_Crop_Mushroom_Block_Brown",
      "rotation": 2
    },
    {
      "x": -10,
      "y": 16,
      "z": -1,
      "name": "Plant_Crop_Mushroom_Block_Red",
      "rotation": 2
    },
    {
      "x": -10,
      "y": 17,
      "z": -1,
      "name": "Plant_Crop_Mushroom_Block_Red",
      "rotation": 2
    },
    {
      "x": -10,
      "y": 44,
      "z": -1,
      "name": "Plant_Crop_Mushroom_Block_Red",
      "rotation": 2
    },
    {
      "x": -10,
      "y": 69,
      "z": -1,
      "name": "Plant_Crop_Mushroom_Block_Brown",
      "rotation": 2
    },
    {
      "x": -10,
      "y": 9,
      "z": 0,
      "name": "Plant_Crop_Mushroom_Block_Brown",
      "rotation": 2
    },
    {
      "x": -10,
      "y": 16,
      "z": 0,
      "name": "Plant_Crop_Mushroom_Block_Red",
      "rotation": 2
    },
    {
      "x": -10,
      "y": 44,
      "z": 0,
      "name": "Plant_Crop_Mushroom_Block_Brown",
      "rotation": 2
    },
    {
      "x": -10,
      "y": 50,
      "z": 0,
      "name": "Plant_Crop_Mushroom_Block_Brown",
      "rotation": 2
    },
    {
      "x": -10,
      "y": 51,
      "z": 0,
      "name": "Plant_Crop_Mushroom_Block_Brown",
      "rotation": 2
    },
    {
      "x": -10,
      "y": 74,
      "z": 0,
      "name": "Plant_Crop_Mushroom_Block_Brown",
      "rotation": 2
    },
    {
      "x": -10,
      "y": 9,
      "z": 1,
      "name": "Plant_Crop_Mushroom_Block_Brown",
      "rotation": 2
    },
    {
      "x": -10,
      "y": 22,
      "z": 1,
      "name": "Plant_Crop_Mushroom_Block_Brown",
      "rotation": 2
    },
    {
      "x": -10,
      "y": 50,
      "z": 1,
      "name": "Plant_Crop_Mushroom_Block_Brown",
      "rotation": 2
    },
    {
      "x": -10,
      "y": 72,
      "z": 1,
      "name": "Plant_Crop_Mushroom_Block_Brown",
      "rotation": 2
    },
    {
      "x": -10,
      "y": 22,
      "z": 2,
      "name": "Plant_Crop_Mushroom_Block_Brown",
      "rotation": 2
    },
    {
      "x": -10,
      "y": 33,
      "z": 2,
      "name": "Plant_Crop_Mushroom_Block_Brown",
      "rotation": 2
    },
    {
      "x": -10,
      "y": 79,
      "z": 2,
      "name": "Plant_Crop_Mushroom_Block_Brown",
      "rotation": 2
    },
    {
      "x": -10,
      "y": 22,
      "z": 3,
      "name": "Plant_Crop_Mushroom_Block_Brown",
      "rotation": 2
    },
    {
      "x": -10,
      "y": 22,
      "z": 4,
      "name": "Plant_Crop_Mushroom_Block_Brown",
      "rotation": 2
    },
    {
      "x": -9,
      "y": 12,
      "z": -3,
      "name": "Plant_Crop_Mushroom_Block_Red"
    },
    {
      "x": -9,
      "y": 16,
      "z": -3,
      "name": "Plant_Crop_Mushroom_Block_Red",
      "rotation": 2
    },
    {
      "x": -9,
      "y": 31,
      "z": -3,
      "name": "Plant_Crop_Mushroom_Block_Red",
      "rotation": 2
    },
    {
      "x": -9,
      "y": 44,
      "z": -3,
      "name": "Plant_Crop_Mushroom_Block_Red",
      "rotation": 2
    },
    {
      "x": -9,
      "y": 47,
      "z": -3,
      "name": "Plant_Crop_Mushroom_Block_Brown",
      "rotation": 2
    },
    {
      "x": -9,
      "y": 53,
      "z": -3,
      "name": "Plant_Crop_Mushroom_Block_Red",
      "rotation": 2
    },
    {
      "x": -9,
      "y": 64,
      "z": -3,
      "name": "Plant_Crop_Mushroom_Block_Brown",
      "rotation": 2
    },
    {
      "x": -9,
      "y": 80,
      "z": -3,
      "name": "Plant_Crop_Mushroom_Block_Brown",
      "rotation": 2
    },
    {
      "x": -9,
      "y": 9,
      "z": -2,
      "name": "Plant_Crop_Mushroom_Block_Brown",
      "rotation": 2
    },
    {
      "x": -9,
      "y": 16,
      "z": -2,
      "name": "Plant_Crop_Mushroom_Block_Red",
      "rotation": 2
    },
    {
      "x": -9,
      "y": 17,
      "z": -2,
      "name": "Plant_Crop_Mushroom_Block_Red",
      "rotation": 2
    },
    {
      "x": -9,
      "y": 31,
      "z": -2,
      "name": "Plant_Crop_Mushroom_Block_Red",
      "rotation": 2
    },
    {
      "x": -9,
      "y": 44,
      "z": -2,
      "name": "Plant_Crop_Mushroom_Block_Red_Trunk",
      "rotation": 2
    },
    {
      "x": -9,
      "y": 45,
      "z": -2,
      "name": "Plant_Crop_Mushroom_Block_Red",
      "rotation": 2
    },
    {
      "x": -9,
      "y": 47,
      "z": -2,
      "name": "Plant_Crop_Mushroom_Block_Brown",
      "rotation": 2
    },
    {
      "x": -9,
      "y": 53,
      "z": -2,
      "name": "Plant_Crop_Mushroom_Block_Red_Trunk",
      "rotation": 2
    },
    {
      "x": -9,
      "y": 54,
      "z": -2,
      "name": "Plant_Crop_Mushroom_Block_Red",
      "rotation": 2
    },
    {
      "x": -9,
      "y": 63,
      "z": -2,
      "name": "Plant_Crop_Mushroom_Block_Brown_Trunk",
      "rotation": 2
    },
    {
      "x": -9,
      "y": 64,
      "z": -2,
      "name": "Plant_Crop_Mushroom_Block_Brown",
      "rotation": 2
    },
    {
      "x": -9,
      "y": 69,
      "z": -2,
      "name": "Plant_Crop_Mushroom_Block_Brown",
      "rotation": 2
    },
    {
      "x": -9,
      "y": 74,
      "z": -2,
      "name": "Plant_Crop_Mushroom_Block_Brown",
      "rotation": 2
    },
    {
      "x": -9,
      "y": 79,
      "z": -2,
      "name": "Plant_Crop_Mushroom_Block_Brown_Trunk",
      "rotation": 2
    },
    {
      "x": -9,
      "y": 80,
      "z": -2,
      "name": "Plant_Crop_Mushroom_Block_Brown",
      "rotation": 2
    },
    {
      "x": -9,
      "y": 87,
      "z": -2,
      "name": "Plant_Crop_Mushroom_Block_Brown",
      "rotation": 2
    },
    {
      "x": -9,
      "y": 1,
      "z": -1,
      "name": "Plant_Crop_Mushroom_Block_Red",
      "rotation": 2
    },
    {
      "x": -9,
      "y": 2,
      "z": -1,
      "name": "Plant_Crop_Mushroom_Block_Red",
      "rotation": 2
    },
    {
      "x": -9,
      "y": 9,
      "z": -1,
      "name": "Plant_Crop_Mushroom_Block_Brown",
      "rotation": 2
    },
    {
      "x": -9,
      "y": 16,
      "z": -1,
      "name": "Plant_Crop_Mushroom_Block_Red_Trunk",
      "rotation": 2
    },
    {
      "x": -9,
      "y": 17,
      "z": -1,
      "name": "Plant_Crop_Mushroom_Block_Red",
      "rotation": 2
    },
    {
      "x": -9,
      "y": 26,
      "z": -1,
      "name": "Plant_Crop_Mushroom_Block_Brown",
      "rotation": 2
    },
    {
      "x": -9,
      "y": 31,
      "z": -1,
      "name": "Plant_Crop_Mushroom_Block_Red",
      "rotation": 2
    },
    {
      "x": -9,
      "y": 32,
      "z": -1,
      "name": "Plant_Crop_Mushroom_Block_Red",
      "rotation": 2
    },
    {
      "x": -9,
      "y": 37,
      "z": -1,
      "name": "Plant_Crop_Mushroom_Block_Red",
      "rotation": 2
    },
    {
      "x": -9,
      "y": 41,
      "z": -1,
      "name": "Plant_Crop_Mushroom_Block_Brown",
      "rotation": 2
    },
    {
      "x": -9,
      "y": 44,
      "z": -1,
      "name": "Plant_Crop_Mushroom_Block_Brown",
      "rotation": 2
    },
    {
      "x": -9,
      "y": 47,
      "z": -1,
      "name": "Plant_Crop_Mushroom_Block_Brown",
      "rotation": 2
    },
    {
      "x": -9,
      "y": 51,
      "z": -1,
      "name": "Plant_Crop_Mushroom_Block_Brown",
      "rotation": 2
    },
    {
      "x": -9,
      "y": 53,
      "z": -1,
      "name": "Plant_Crop_Mushroom_Block_Red",
      "rotation": 2
    },
    {
      "x": -9,
      "y": 57,
      "z": -1,
      "name": "Plant_Crop_Mushroom_Block_Brown",
      "rotation": 2
    },
    {
      "x": -9,
      "y": 59,
      "z": -1,
      "name": "Plant_Crop_Mushroom_Block_Red",
      "rotation": 2
    },
    {
      "x": -9,
      "y": 64,
      "z": -1,
      "name": "Plant_Crop_Mushroom_Block_Brown",
      "rotation": 2
    },
    {
      "x": -9,
      "y": 68,
      "z": -1,
      "name": "Plant_Crop_Mushroom_Block_Brown_Trunk",
      "rotation": 2
    },
    {
      "x": -9,
      "y": 69,
      "z": -1,
      "name": "Plant_Crop_Mushroom_Block_Brown",
      "rotation": 2
    },
    {
      "x": -9,
      "y": 70,
      "z": -1,
      "name": "Plant_Crop_Mushroom_Block_Brown",
      "rotation": 2
    },
    {
      "x": -9,
      "y": 74,
      "z": -1,
      "name": "Plant_Crop_Mushroom_Block_Brown",
      "rotation": 2
    },
    {
      "x": -9,
      "y": 77,
      "z": -1,
      "name": "Plant_Crop_Mushroom_Block_Red",
      "rotation": 2
    },
    {
      "x": -9,
      "y": 80,
      "z": -1,
      "name": "Plant_Crop_Mushroom_Block_Brown",
      "rotation": 2
    },
    {
      "x": -9,
      "y": 3,
      "z": 0,
      "name": "Plant_Crop_Mushroom_Block_Red",
      "rotation": 2
    },
    {
      "x": -9,
      "y": 8,
      "z": 0,
      "name": "Plant_Crop_Mushroom_Block_Brown_Trunk",
      "rotation": 2
    },
    {
      "x": -9,
      "y": 9,
      "z": 0,
      "name": "Plant_Crop_Mushroom_Block_Brown",
      "rotation": 2
    },
    {
      "x": -9,
      "y": 10,
      "z": 0,
      "name": "Plant_Crop_Mushroom_Block_Brown",
      "rotation": 2
    },
    {
      "x": -9,
      "y": 13,
      "z": 0,
      "name": "Plant_Crop_Mushroom_Block_Brown",
      "rotation": 2
    },
    {
      "x": -9,
      "y": 16,
      "z": 0,
      "name": "Plant_Crop_Mushroom_Block_Red",
      "rotation": 2
    },
    {
      "x": -9,
      "y": 17,
      "z": 0,
      "name": "Plant_Crop_Mushroom_Block_Red",
      "rotation": 2
    },
    {
      "x": -9,
      "y": 19,
      "z": 0,
      "name": "Plant_Crop_Mushroom_Block_Red",
      "rotation": 2
    },
    {
      "x": -9,
      "y": 22,
      "z": 0,
      "name": "Plant_Crop_Mushroom_Block_Brown",
      "rotation": 2
    },
    {
      "x": -9,
      "y": 26,
      "z": 0,
      "name": "Plant_Crop_Mushroom_Block_Brown",
      "rotation": 2
    },
    {
      "x": -9,
      "y": 34,
      "z": 0,
      "name": "Plant_Crop_Mushroom_Block_Brown",
      "rotation": 2
    },
    {
      "x": -9,
      "y": 37,
      "z": 0,
      "name": "Plant_Crop_Mushroom_Block_Brown",
      "rotation": 2
    },
    {
      "x": -9,
      "y": 43,
      "z": 0,
      "name": "Plant_Crop_Mushroom_Block_Brown_Trunk",
      "rotation": 2
    },
    {
      "x": -9,
      "y": 44,
      "z": 0,
      "name": "Plant_Crop_Mushroom_Block_Brown",
      "rotation": 2
    },
    {
      "x": -9,
      "y": 45,
      "z": 0,
      "name": "Plant_Crop_Mushroom_Block_Brown",
      "rotation": 2
    },
    {
      "x": -9,
      "y": 50,
      "z": 0,
      "name": "Plant_Crop_Mushroom_Block_Brown_Trunk",
      "rotation": 2
    },
    {
      "x": -9,
      "y": 51,
      "z": 0,
      "name": "Plant_Crop_Mushroom_Block_Brown",
      "rotation": 2
    },
    {
      "x": -9,
      "y": 52,
      "z": 0,
      "name": "Plant_Crop_Mushroom_Block_Brown",
      "rotation": 2
    },
    {
      "x": -9,
      "y": 59,
      "z": 0,
      "name": "Plant_Crop_Mushroom_Block_Red",
      "rotation": 2
    },
    {
      "x": -9,
      "y": 66,
      "z": 0,
      "name": "Plant_Crop_Mushroom_Block_Red",
      "rotation": 2
    },
    {
      "x": -9,
      "y": 69,
      "z": 0,
      "name": "Plant_Crop_Mushroom_Block_Brown",
      "rotation": 2
    },
    {
      "x": -9,
      "y": 72,
      "z": 0,
      "name": "Plant_Crop_Mushroom_Block_Brown",
      "rotation": 2
    },
    {
      "x": -9,
      "y": 74,
      "z": 0,
      "name": "Plant_Crop_Mushroom_Block_Brown",
      "rotation": 2
    },
    {
      "x": -9,
      "y": 75,
      "z": 0,
      "name": "Plant_Crop_Mushroom_Block_Brown",
      "rotation": 2
    },
    {
      "x": -9,
      "y": 79,
      "z": 0,
      "name": "Plant_Crop_Mushroom_Block_Red",
      "rotation": 2
    },
    {
      "x": -9,
      "y": 84,
      "z": 0,
      "name": "Plant_Crop_Mushroom_Block_Brown",
      "rotation": 2
    },
    {
      "x": -9,
      "y": 5,
      "z": 1,
      "name": "Plant_Crop_Mushroom_Block_Brown",
      "rotation": 2
    },
    {
      "x": -9,
      "y": 9,
      "z": 1,
      "name": "Plant_Crop_Mushroom_Block_Brown",
      "rotation": 2
    },
    {
      "x": -9,
      "y": 16,
      "z": 1,
      "name": "Plant_Crop_Mushroom_Block_Red",
      "rotation": 2
    },
    {
      "x": -9,
      "y": 22,
      "z": 1,
      "name": "Plant_Crop_Mushroom_Block_Brown",
      "rotation": 2
    },
    {
      "x": -9,
      "y": 23,
      "z": 1,
      "name": "Plant_Crop_Mushroom_Block_Brown",
      "rotation": 2
    },
    {
      "x": -9,
      "y": 25,
      "z": 1,
      "name": "Plant_Crop_Mushroom_Block_Red",
      "rotation": 2
    },
    {
      "x": -9,
      "y": 26,
      "z": 1,
      "name": "Plant_Crop_Mushroom_Block_Brown",
      "rotation": 2
    },
    {
      "x": -9,
      "y": 28,
      "z": 1,
      "name": "Plant_Crop_Mushroom_Block_Red",
      "rotation": 2
    },
    {
      "x": -9,
      "y": 33,
      "z": 1,
      "name": "Plant_Crop_Mushroom_Block_Brown",
      "rotation": 2
    },
    {
      "x": -9,
      "y": 37,
      "z": 1,
      "name": "Plant_Crop_Mushroom_Block_Brown",
      "rotation": 2
    },
    {
      "x": -9,
      "y": 39,
      "z": 1,
      "name": "Plant_Crop_Mushroom_Block_Red",
      "rotation": 2
    },
    {
      "x": -9,
      "y": 44,
      "z": 1,
      "name": "Plant_Crop_Mushroom_Block_Brown",
      "rotation": 2
    },
    {
      "x": -9,
      "y": 49,
      "z": 1,
      "name": "Plant_Crop_Mushroom_Block_Brown_Trunk",
      "rotation": 2
    },
    {
      "x": -9,
      "y": 50,
      "z": 1,
      "name": "Plant_Crop_Mushroom_Block_Brown",
      "rotation": 2
    },
    {
      "x": -9,
      "y": 51,
      "z": 1,
      "name": "Plant_Crop_Mushroom_Block_Brown",
      "rotation": 2
    },
    {
      "x": -9,
      "y": 55,
      "z": 1,
      "name": "Plant_Crop_Mushroom_Block_Red",
      "rotation": 2
    },
    {
      "x": -9,
      "y": 58,
      "z": 1,
      "name": "Plant_Crop_Mushroom_Block_Brown",
      "rotation": 2
    },
    {
      "x": -9,
      "y": 59,
      "z": 1,
      "name": "Plant_Crop_Mushroom_Block_Red",
      "rotation": 2
    },
    {
      "x": -9,
      "y": 67,
      "z": 1,
      "name": "Plant_Crop_Mushroom_Block_Brown",
      "rotation": 2
    },
    {
      "x": -9,
      "y": 72,
      "z": 1,
      "name": "Plant_Crop_Mushroom_Block_Brown",
      "rotation": 2
    },
    {
      "x": -9,
      "y": 74,
      "z": 1,
      "name": "Plant_Crop_Mushroom_Block_Brown",
      "rotation": 2
    },
    {
      "x": -9,
      "y": 79,
      "z": 1,
      "name": "Plant_Crop_Mushroom_Block_Brown",
      "rotation": 2
    },
    {
      "x": -9,
      "y": 82,
      "z": 1,
      "name": "Plant_Crop_Mushroom_Block_Brown",
      "rotation": 2
    },
    {
      "x": -9,
      "y": 87,
      "z": 1,
      "name": "Plant_Crop_Mushroom_Block_Red",
      "rotation": 2
    },
    {
      "x": -9,
      "y": 4,
      "z": 2,
      "name": "Plant_Crop_Mushroom_Block_Brown_Trunk",
      "rotation": 2
    },
    {
      "x": -9,
      "y": 5,
      "z": 2,
      "name": "Plant_Crop_Mushroom_Block_Brown",
      "rotation": 2
    },
    {
      "x": -9,
      "y": 6,
      "z": 2,
      "name": "Plant_Crop_Mushroom_Block_Brown",
      "rotation": 2
    },
    {
      "x": -9,
      "y": 9,
      "z": 2,
      "name": "Plant_Crop_Mushroom_Block_Brown",
      "rotation": 2
    },
    {
      "x": -9,
      "y": 21,
      "z": 2,
      "name": "Plant_Crop_Mushroom_Block_Brown_Trunk",
      "rotation": 2
    },
    {
      "x": -9,
      "y": 22,
      "z": 2,
      "name": "Plant_Crop_Mushroom_Block_Brown",
      "rotation": 2
    },
    {
      "x": -9,
      "y": 23,
      "z": 2,
      "name": "Plant_Crop_Mushroom_Block_Brown",
      "rotation": 2
    },
    {
      "x": -9,
      "y": 25,
      "z": 2,
      "name": "Plant_Crop_Mushroom_Block_Red",
      "rotation": 2
    },
    {
      "x": -9,
      "y": 33,
      "z": 2,
      "name": "Plant_Crop_Mushroom_Block_Brown_Trunk",
      "rotation": 2
    },
    {
      "x": -9,
      "y": 34,
      "z": 2,
      "name": "Plant_Crop_Mushroom_Block_Brown",
      "rotation": 2
    },
    {
      "x": -9,
      "y": 37,
      "z": 2,
      "name": "Plant_Crop_Mushroom_Block_Brown",
      "rotation": 2
    },
    {
      "x": -9,
      "y": 39,
      "z": 2,
      "name": "Plant_Crop_Mushroom_Block_Red",
      "rotation": 2
    },
    {
      "x": -9,
      "y": 50,
      "z": 2,
      "name": "Plant_Crop_Mushroom_Block_Brown",
      "rotation": 2
    },
    {
      "x": -9,
      "y": 52,
      "z": 2,
      "name": "Plant_Crop_Mushroom_Block_Red",
      "rotation": 2
    },
    {
      "x": -9,
      "y": 58,
      "z": 2,
      "name": "Plant_Crop_Mushroom_Block_Brown",
      "rotation": 2
    },
    {
      "x": -9,
      "y": 67,
      "z": 2,
      "name": "Plant_Crop_Mushroom_Block_Brown",
      "rotation": 2
    },
    {
      "x": -9,
      "y": 72,
      "z": 2,
      "name": "Plant_Crop_Mushroom_Block_Brown",
      "rotation": 2
    },
    {
      "x": -9,
      "y": 79,
      "z": 2,
      "name": "Plant_Crop_Mushroom_Block_Brown",
      "rotation": 2
    },
    {
      "x": -9,
      "y": 80,
      "z": 2,
      "name": "Plant_Crop_Mushroom_Block_Brown",
      "rotation": 2
    },
    {
      "x": -9,
      "y": 87,
      "z": 2,
      "name": "Plant_Crop_Mushroom_Block_Red",
      "rotation": 2
    },
    {
      "x": -9,
      "y": 5,
      "z": 3,
      "name": "Plant_Crop_Mushroom_Block_Brown",
      "rotation": 2
    },
    {
      "x": -9,
      "y": 22,
      "z": 3,
      "name": "Plant_Crop_Mushroom_Block_Brown",
      "rotation": 2
    },
    {
      "x": -9,
      "y": 23,
      "z": 3,
      "name": "Plant_Crop_Mushroom_Block_Brown",
      "rotation": 2
    },
    {
      "x": -9,
      "y": 25,
      "z": 3,
      "name": "Plant_Crop_Mushroom_Block_Red",
      "rotation": 2
    },
    {
      "x": -9,
      "y": 33,
      "z": 3,
      "name": "Plant_Crop_Mushroom_Block_Brown",
      "rotation": 2
    },
    {
      "x": -9,
      "y": 39,
      "z": 3,
      "name": "Plant_Crop_Mushroom_Block_Red",
      "rotation": 2
    },
    {
      "x": -9,
      "y": 63,
      "z": 3,
      "name": "Plant_Crop_Mushroom_Block_Red",
      "rotation": 2
    },
    {
      "x": -9,
      "y": 67,
      "z": 3,
      "name": "Plant_Crop_Mushroom_Block_Brown",
      "rotation": 2
    },
    {
      "x": -9,
      "y": 74,
      "z": 3,
      "name": "Plant_Crop_Mushroom_Block_Red",
      "rotation": 2
    },
    {
      "x": -9,
      "y": 79,
      "z": 3,
      "name": "Plant_Crop_Mushroom_Block_Brown",
      "rotation": 2
    },
    {
      "x": -9,
      "y": 87,
      "z": 3,
      "name": "Plant_Crop_Mushroom_Block_Red",
      "rotation": 2
    },
    {
      "x": -9,
      "y": 88,
      "z": 3,
      "name": "Plant_Crop_Mushroom_Block_Red",
      "rotation": 2
    },
    {
      "x": -9,
      "y": 22,
      "z": 4,
      "name": "Plant_Crop_Mushroom_Block_Brown",
      "rotation": 2
    },
    {
      "x": -9,
      "y": 23,
      "z": 4,
      "name": "Plant_Crop_Mushroom_Block_Brown",
      "rotation": 2
    },
    {
      "x": -8,
      "y": 18,
      "z": -5,
      "name": "Plant_Crop_Mushroom_Block_Brown"
    },
    {
      "x": -8,
      "y": 22,
      "z": -5,
      "name": "Plant_Crop_Mushroom_Block_Red"
    },
    {
      "x": -8,
      "y": 76,
      "z": -5,
      "name": "Plant_Crop_Mushroom_Block_Red"
    },
    {
      "x": -8,
      "y": 79,
      "z": -5,
      "name": "Plant_Crop_Mushroom_Block_Red"
    },
    {
      "x": -8,
      "y": 4,
      "z": -4,
      "name": "Plant_Crop_Mushroom_Block_Brown"
    },
    {
      "x": -8,
      "y": 12,
      "z": -4,
      "name": "Plant_Crop_Mushroom_Block_Red"
    },
    {
      "x": -8,
      "y": 15,
      "z": -4,
      "name": "Plant_Crop_Mushroom_Block_Brown"
    },
    {
      "x": -8,
      "y": 24,
      "z": -4,
      "name": "Plant_Crop_Mushroom_Block_Brown"
    },
    {
      "x": -8,
      "y": 39,
      "z": -4,
      "name": "Plant_Crop_Mushroom_Block_Red"
    },
    {
      "x": -8,
      "y": 42,
      "z": -4,
      "name": "Plant_Crop_Mushroom_Block_Red",
      "rotation": 2
    },
    {
      "x": -8,
      "y": 54,
      "z": -4,
      "name": "Plant_Crop_Mushroom_Block_Red"
    },
    {
      "x": -8,
      "y": 62,
      "z": -4,
      "name": "Plant_Crop_Mushroom_Block_Red"
    },
    {
      "x": -8,
      "y": 67,
      "z": -4,
      "name": "Plant_Crop_Mushroom_Block_Brown"
    },
    {
      "x": -8,
      "y": 76,
      "z": -4,
      "name": "Plant_Crop_Mushroom_Block_Red"
    },
    {
      "x": -8,
      "y": 86,
      "z": -4,
      "name": "Plant_Crop_Mushroom_Block_Brown"
    },
    {
      "x": -8,
      "y": 8,
      "z": -3,
      "name": "Plant_Crop_Mushroom_Block_Brown"
    },
    {
      "x": -8,
      "y": 11,
      "z": -3,
      "name": "Plant_Crop_Mushroom_Block_Red_Trunk"
    },
    {
      "x": -8,
      "y": 12,
      "z": -3,
      "name": "Plant_Crop_Mushroom_Block_Red"
    },
    {
      "x": -8,
      "y": 13,
      "z": -3,
      "name": "Plant_Crop_Mushroom_Block_Red"
    },
    {
      "x": -8,
      "y": 16,
      "z": -3,
      "name": "Plant_Crop_Mushroom_Block_Red",
      "rotation": 2
    },
    {
      "x": -8,
      "y": 23,
      "z": -3,
      "name": "Plant_Crop_Mushroom_Block_Brown"
    },
    {
      "x": -8,
      "y": 24,
      "z": -3,
      "name": "Plant_Crop_Mushroom_Block_Brown"
    },
    {
      "x": -8,
      "y": 31,
      "z": -3,
      "name": "Plant_Crop_Mushroom_Block_Red",
      "rotation": 2
    },
    {
      "x": -8,
      "y": 35,
      "z": -3,
      "name": "Plant_Crop_Mushroom_Block_Brown"
    },
    {
      "x": -8,
      "y": 42,
      "z": -3,
      "name": "Plant_Crop_Mushroom_Block_Red",
      "rotation": 2
    },
    {
      "x": -8,
      "y": 44,
      "z": -3,
      "name": "Plant_Crop_Mushroom_Block_Red",
      "rotation": 2
    },
    {
      "x": -8,
      "y": 47,
      "z": -3,
      "name": "Plant_Crop_Mushroom_Block_Brown",
      "rotation": 2
    },
    {
      "x": -8,
      "y": 53,
      "z": -3,
      "name": "Plant_Crop_Mushroom_Block_Red",
      "rotation": 2
    },
    {
      "x": -8,
      "y": 64,
      "z": -3,
      "name": "Plant_Crop_Mushroom_Block_Brown",
      "rotation": 2
    },
    {
      "x": -8,
      "y": 67,
      "z": -3,
      "name": "Plant_Crop_Mushroom_Block_Brown"
    },
    {
      "x": -8,
      "y": 74,
      "z": -3,
      "name": "Plant_Crop_Mushroom_Block_Brown",
      "rotation": 2
    },
    {
      "x": -8,
      "y": 80,
      "z": -3,
      "name": "Plant_Crop_Mushroom_Block_Brown",
      "rotation": 2
    },
    {
      "x": -8,
      "y": 87,
      "z": -3,
      "name": "Plant_Crop_Mushroom_Block_Brown",
      "rotation": 2
    },
    {
      "x": -8,
      "y": 1,
      "z": -2,
      "name": "Plant_Crop_Mushroom_Block_Red",
      "rotation": 2
    },
    {
      "x": -8,
      "y": 9,
      "z": -2,
      "name": "Plant_Crop_Mushroom_Block_Brown",
      "rotation": 2
    },
    {
      "x": -8,
      "y": 12,
      "z": -2,
      "name": "Plant_Crop_Mushroom_Block_Red"
    },
    {
      "x": -8,
      "y": 16,
      "z": -2,
      "name": "Plant_Crop_Mushroom_Block_Red",
      "rotation": 2
    },
    {
      "x": -8,
      "y": 17,
      "z": -2,
      "name": "Plant_Crop_Mushroom_Block_Red",
      "rotation": 2
    },
    {
      "x": -8,
      "y": 23,
      "z": -2,
      "name": "Plant_Crop_Mushroom_Block_Brown"
    },
    {
      "x": -8,
      "y": 30,
      "z": -2,
      "name": "Plant_Crop_Mushroom_Block_Red_Trunk",
      "rotation": 2
    },
    {
      "x": -8,
      "y": 31,
      "z": -2,
      "name": "Plant_Crop_Mushroom_Block_Red_Trunk",
      "rotation": 2
    },
    {
      "x": -8,
      "y": 32,
      "z": -2,
      "name": "Plant_Crop_Mushroom_Block_Red",
      "rotation": 2
    },
    {
      "x": -8,
      "y": 35,
      "z": -2,
      "name": "Plant_Crop_Mushroom_Block_Brown"
    },
    {
      "x": -8,
      "y": 37,
      "z": -2,
      "name": "Plant_Crop_Mushroom_Block_Red",
      "rotation": 2
    },
    {
      "x": -8,
      "y": 41,
      "z": -2,
      "name": "Plant_Crop_Mushroom_Block_Brown",
      "rotation": 2
    },
    {
      "x": -8,
      "y": 42,
      "z": -2,
      "name": "Plant_Crop_Mushroom_Block_Red",
      "rotation": 2
    },
    {
      "x": -8,
      "y": 43,
      "z": -2,
      "name": "Plant_Crop_Mushroom_Block_Red_Trunk",
      "rotation": 2
    },
    {
      "x": -8,
      "y": 44,
      "z": -2,
      "name": "Plant_Crop_Mushroom_Block_Red_Trunk",
      "rotation": 2
    },
    {
      "x": -8,
      "y": 45,
      "z": -2,
      "name": "Plant_Crop_Mushroom_Block_Red",
      "rotation": 2
    },
    {
      "x": -8,
      "y": 46,
      "z": -2,
      "name": "Plant_Crop_Mushroom_Block_Brown_Trunk",
      "rotation": 2
    },
    {
      "x": -8,
      "y": 47,
      "z": -2,
      "name": "Plant_Crop_Mushroom_Block_Brown",
      "rotation": 2
    },
    {
      "x": -8,
      "y": 48,
      "z": -2,
      "name": "Plant_Crop_Mushroom_Block_Brown",
      "rotation": 2
    },
    {
      "x": -8,
      "y": 51,
      "z": -2,
      "name": "Plant_Crop_Mushroom_Block_Red_Trunk",
      "rotation": 2
    },
    {
      "x": -8,
      "y": 52,
      "z": -2,
      "name": "Plant_Crop_Mushroom_Block_Red_Trunk",
      "rotation": 2
    },
    {
      "x": -8,
      "y": 53,
      "z": -2,
      "name": "Plant_Crop_Mushroom_Block_Red_Trunk",
      "rotation": 2
    },
    {
      "x": -8,
      "y": 54,
      "z": -2,
      "name": "Plant_Crop_Mushroom_Block_Red",
      "rotation": 2
    },
    {
      "x": -8,
      "y": 57,
      "z": -2,
      "name": "Plant_Crop_Mushroom_Block_Brown",
      "rotation": 2
    },
    {
      "x": -8,
      "y": 61,
      "z": -2,
      "name": "Plant_Crop_Mushroom_Block_Brown_Trunk",
      "rotation": 2
    },
    {
      "x": -8,
      "y": 62,
      "z": -2,
      "name": "Plant_Crop_Mushroom_Block_Brown_Trunk",
      "rotation": 2
    },
    {
      "x": -8,
      "y": 63,
      "z": -2,
      "name": "Plant_Crop_Mushroom_Block_Brown_Trunk",
      "rotation": 2
    },
    {
      "x": -8,
      "y": 64,
      "z": -2,
      "name": "Plant_Crop_Mushroom_Block_Brown",
      "rotation": 2
    },
    {
      "x": -8,
      "y": 65,
      "z": -2,
      "name": "Plant_Crop_Mushroom_Block_Brown",
      "rotation": 2
    },
    {
      "x": -8,
      "y": 67,
      "z": -2,
      "name": "Plant_Crop_Mushroom_Block_Brown"
    },
    {
      "x": -8,
      "y": 69,
      "z": -2,
      "name": "Plant_Crop_Mushroom_Block_Brown",
      "rotation": 2
    },
    {
      "x": -8,
      "y": 72,
      "z": -2,
      "name": "Plant_Crop_Mushroom_Block_Brown_Trunk",
      "rotation": 2
    },
    {
      "x": -8,
      "y": 73,
      "z": -2,
      "name": "Plant_Crop_Mushroom_Block_Brown_Trunk",
      "rotation": 2
    },
    {
      "x": -8,
      "y": 74,
      "z": -2,
      "name": "Plant_Crop_Mushroom_Block_Brown",
      "rotation": 2
    },
    {
      "x": -8,
      "y": 75,
      "z": -2,
      "name": "Plant_Crop_Mushroom_Block_Brown",
      "rotation": 2
    },
    {
      "x": -8,
      "y": 77,
      "z": -2,
      "name": "Plant_Crop_Mushroom_Block_Red",
      "rotation": 2
    },
    {
      "x": -8,
      "y": 78,
      "z": -2,
      "name": "Plant_Crop_Mushroom_Block_Brown_Trunk",
      "rotation": 2
    },
    {
      "x": -8,
      "y": 79,
      "z": -2,
      "name": "Plant_Crop_Mushroom_Block_Brown_Trunk",
      "rotation": 2
    },
    {
      "x": -8,
      "y": 80,
      "z": -2,
      "name": "Plant_Crop_Mushroom_Block_Brown",
      "rotation": 2
    },
    {
      "x": -8,
      "y": 81,
      "z": -2,
      "name": "Plant_Crop_Mushroom_Block_Brown",
      "rotation": 2
    },
    {
      "x": -8,
      "y": 86,
      "z": -2,
      "name": "Plant_Crop_Mushroom_Block_Brown_Trunk",
      "rotation": 2
    },
    {
      "x": -8,
      "y": 87,
      "z": -2,
      "name": "Plant_Crop_Mushroom_Block_Brown",
      "rotation": 2
    },
    {
      "x": -8,
      "y": 88,
      "z": -2,
      "name": "Plant_Crop_Mushroom_Block_Brown",
      "rotation": 2
    },
    {
      "x": -8,
      "y": 0,
      "z": -1,
      "name": "Plant_Crop_Mushroom_Block_Red_Trunk",
      "rotation": 2
    },
    {
      "x": -8,
      "y": 1,
      "z": -1,
      "name": "Plant_Crop_Mushroom_Block_Red_Trunk",
      "rotation": 2
    },
    {
      "x": -8,
      "y": 2,
      "z": -1,
      "name": "Plant_Crop_Mushroom_Block_Red",
      "rotation": 2
    },
    {
      "x": -8,
      "y": 3,
      "z": -1,
      "name": "Plant_Crop_Mushroom_Block_Red",
      "rotation": 2
    },
    {
      "x": -8,
      "y": 9,
      "z": -1,
      "name": "Plant_Crop_Mushroom_Block_Brown",
      "rotation": 2
    },
    {
      "x": -8,
      "y": 10,
      "z": -1,
      "name": "Plant_Crop_Mushroom_Block_Brown",
      "rotation": 2
    },
    {
      "x": -8,
      "y": 13,
      "z": -1,
      "name": "Plant_Crop_Mushroom_Block_Brown",
      "rotation": 2
    },
    {
      "x": -8,
      "y": 14,
      "z": -1,
      "name": "Plant_Crop_Mushroom_Block_Red_Trunk",
      "rotation": 2
    },
    {
      "x": -8,
      "y": 15,
      "z": -1,
      "name": "Plant_Crop_Mushroom_Block_Red_Trunk",
      "rotation": 2
    },
    {
      "x": -8,
      "y": 16,
      "z": -1,
      "name": "Plant_Crop_Mushroom_Block_Red_Trunk",
      "rotation": 2
    },
    {
      "x": -8,
      "y": 17,
      "z": -1,
      "name": "Plant_Crop_Mushroom_Block_Red",
      "rotation": 2
    },
    {
      "x": -8,
      "y": 19,
      "z": -1,
      "name": "Plant_Crop_Mushroom_Block_Red",
      "rotation": 2
    },
    {
      "x": -8,
      "y": 26,
      "z": -1,
      "name": "Plant_Crop_Mushroom_Block_Brown",
      "rotation": 2
    },
    {
      "x": -8,
      "y": 31,
      "z": -1,
      "name": "Plant_Crop_Mushroom_Block_Red",
      "rotation": 2
    },
    {
      "x": -8,
      "y": 32,
      "z": -1,
      "name": "Plant_Crop_Mushroom_Block_Red_Trunk",
      "rotation": 2
    },
    {
      "x": -8,
      "y": 33,
      "z": -1,
      "name": "Plant_Crop_Mushroom_Block_Red",
      "rotation": 2
    },
    {
      "x": -8,
      "y": 34,
      "z": -1,
      "name": "Plant_Crop_Mushroom_Block_Brown",
      "rotation": 2
    },
    {
      "x": -8,
      "y": 36,
      "z": -1,
      "name": "Plant_Crop_Mushroom_Block_Red_Trunk",
      "rotation": 2
    },
    {
      "x": -8,
      "y": 37,
      "z": -1,
      "name": "Plant_Crop_Mushroom_Block_Red_Trunk",
      "rotation": 2
    },
    {
      "x": -8,
      "y": 38,
      "z": -1,
      "name": "Plant_Crop_Mushroom_Block_Red",
      "rotation": 2
    },
    {
      "x": -8,
      "y": 40,
      "z": -1,
      "name": "Plant_Crop_Mushroom_Block_Brown_Trunk",
      "rotation": 2
    },
    {
      "x": -8,
      "y": 41,
      "z": -1,
      "name": "Plant_Crop_Mushroom_Block_Brown_Trunk",
      "rotation": 2
    },
    {
      "x": -8,
      "y": 42,
      "z": -1,
      "name": "Plant_Crop_Mushroom_Block_Brown",
      "rotation": 2
    },
    {
      "x": -8,
      "y": 44,
      "z": -1,
      "name": "Plant_Crop_Mushroom_Block_Brown",
      "rotation": 2
    },
    {
      "x": -8,
      "y": 47,
      "z": -1,
      "name": "Plant_Crop_Mushroom_Block_Brown",
      "rotation": 2
    },
    {
      "x": -8,
      "y": 51,
      "z": -1,
      "name": "Plant_Crop_Mushroom_Block_Brown",
      "rotation": 2
    },
    {
      "x": -8,
      "y": 53,
      "z": -1,
      "name": "Plant_Crop_Mushroom_Block_Red",
      "rotation": 2
    },
    {
      "x": -8,
      "y": 56,
      "z": -1,
      "name": "Plant_Crop_Mushroom_Block_Brown_Trunk",
      "rotation": 2
    },
    {
      "x": -8,
      "y": 57,
      "z": -1,
      "name": "Plant_Crop_Mushroom_Block_Brown",
      "rotation": 2
    },
    {
      "x": -8,
      "y": 58,
      "z": -1,
      "name": "Plant_Crop_Mushroom_Block_Brown",
      "rotation": 2
    },
    {
      "x": -8,
      "y": 59,
      "z": -1,
      "name": "Plant_Crop_Mushroom_Block_Red",
      "rotation": 2
    },
    {
      "x": -8,
      "y": 64,
      "z": -1,
      "name": "Plant_Crop_Mushroom_Block_Brown",
      "rotation": 2
    },
    {
      "x": -8,
      "y": 66,
      "z": -1,
      "name": "Plant_Crop_Mushroom_Block_Red",
      "rotation": 2
    },
    {
      "x": -8,
      "y": 67,
      "z": -1,
      "name": "Plant_Crop_Mushroom_Block_Brown_Trunk",
      "rotation": 2
    },
    {
      "x": -8,
      "y": 68,
      "z": -1,
      "name": "Plant_Crop_Mushroom_Block_Brown_Trunk",
      "rotation": 2
    },
    {
      "x": -8,
      "y": 69,
      "z": -1,
      "name": "Plant_Crop_Mushroom_Block_Brown",
      "rotation": 2
    },
    {
      "x": -8,
      "y": 70,
      "z": -1,
      "name": "Plant_Crop_Mushroom_Block_Brown",
      "rotation": 2
    },
    {
      "x": -8,
      "y": 74,
      "z": -1,
      "name": "Plant_Crop_Mushroom_Block_Brown",
      "rotation": 2
    },
    {
      "x": -8,
      "y": 75,
      "z": -1,
      "name": "Plant_Crop_Mushroom_Block_Brown",
      "rotation": 2
    },
    {
      "x": -8,
      "y": 76,
      "z": -1,
      "name": "Plant_Crop_Mushroom_Block_Red_Trunk",
      "rotation": 2
    },
    {
      "x": -8,
      "y": 77,
      "z": -1,
      "name": "Plant_Crop_Mushroom_Block_Red_Trunk",
      "rotation": 2
    },
    {
      "x": -8,
      "y": 78,
      "z": -1,
      "name": "Plant_Crop_Mushroom_Block_Red",
      "rotation": 2
    },
    {
      "x": -8,
      "y": 79,
      "z": -1,
      "name": "Plant_Crop_Mushroom_Block_Red",
      "rotation": 2
    },
    {
      "x": -8,
      "y": 80,
      "z": -1,
      "name": "Plant_Crop_Mushroom_Block_Brown",
      "rotation": 2
    },
    {
      "x": -8,
      "y": 84,
      "z": -1,
      "name": "Plant_Crop_Mushroom_Block_Brown",
      "rotation": 2
    },
    {
      "x": -8,
      "y": 87,
      "z": -1,
      "name": "Plant_Crop_Mushroom_Block_Brown",
      "rotation": 2
    },
    {
      "x": -8,
      "y": 1,
      "z": 0,
      "name": "Plant_Crop_Mushroom_Block_Red",
      "rotation": 2
    },
    {
      "x": -8,
      "y": 2,
      "z": 0,
      "name": "Plant_Crop_Mushroom_Block_Red_Trunk",
      "rotation": 2
    },
    {
      "x": -8,
      "y": 3,
      "z": 0,
      "name": "Plant_Crop_Mushroom_Block_Red",
      "rotation": 2
    },
    {
      "x": -8,
      "y": 4,
      "z": 0,
      "name": "Plant_Crop_Mushroom_Block_Red",
      "rotation": 2
    },
    {
      "x": -8,
      "y": 7,
      "z": 0,
      "name": "Plant_Crop_Mushroom_Block_Brown_Trunk",
      "rotation": 2
    },
    {
      "x": -8,
      "y": 8,
      "z": 0,
      "name": "Plant_Crop_Mushroom_Block_Brown_Trunk",
      "rotation": 2
    },
    {
      "x": -8,
      "y": 9,
      "z": 0,
      "name": "Plant_Crop_Mushroom_Block_Brown",
      "rotation": 2
    },
    {
      "x": -8,
      "y": 10,
      "z": 0,
      "name": "Plant_Crop_Mushroom_Block_Brown",
      "rotation": 2
    },
    {
      "x": -8,
      "y": 12,
      "z": 0,
      "name": "Plant_Crop_Mushroom_Block_Brown_Trunk",
      "rotation": 2
    },
    {
      "x": -8,
      "y": 13,
      "z": 0,
      "name": "Plant_Crop_Mushroom_Block_Brown_Trunk",
      "rotation": 2
    },
    {
      "x": -8,
      "y": 14,
      "z": 0,
      "name": "Plant_Crop_Mushroom_Block_Brown",
      "rotation": 2
    },
    {
      "x": -8,
      "y": 16,
      "z": 0,
      "name": "Plant_Crop_Mushroom_Block_Red",
      "rotation": 2
    },
    {
      "x": -8,
      "y": 17,
      "z": 0,
      "name": "Plant_Crop_Mushroom_Block_Red",
      "rotation": 2
    },
    {
      "x": -8,
      "y": 18,
      "z": 0,
      "name": "Plant_Crop_Mushroom_Block_Red_Trunk",
      "rotation": 2
    },
    {
      "x": -8,
      "y": 19,
      "z": 0,
      "name": "Plant_Crop_Mushroom_Block_Red",
      "rotation": 2
    },
    {
      "x": -8,
      "y": 20,
      "z": 0,
      "name": "Plant_Crop_Mushroom_Block_Red",
      "rotation": 2
    },
    {
      "x": -8,
      "y": 22,
      "z": 0,
      "name": "Plant_Crop_Mushroom_Block_Brown",
      "rotation": 2
    },
    {
      "x": -8,
      "y": 25,
      "z": 0,
      "name": "Plant_Crop_Mushroom_Block_Brown_Trunk",
      "rotation": 2
    },
    {
      "x": -8,
      "y": 26,
      "z": 0,
      "name": "Plant_Crop_Mushroom_Block_Brown_Trunk",
      "rotation": 2
    },
    {
      "x": -8,
      "y": 27,
      "z": 0,
      "name": "Plant_Crop_Mushroom_Block_Brown",
      "rotation": 2
    },
    {
      "x": -8,
      "y": 28,
      "z": 0,
      "name": "Plant_Crop_Mushroom_Block_Red",
      "rotation": 2
    },
    {
      "x": -8,
      "y": 32,
      "z": 0,
      "name": "Plant_Crop_Mushroom_Block_Red",
      "rotation": 2
    },
    {
      "x": -8,
      "y": 33,
      "z": 0,
      "name": "Plant_Crop_Mushroom_Block_Brown_Trunk",
      "rotation": 2
    },
    {
      "x": -8,
      "y": 34,
      "z": 0,
      "name": "Plant_Crop_Mushroom_Block_Brown_Trunk",
      "rotation": 2
    },
    {
      "x": -8,
      "y": 35,
      "z": 0,
      "name": "Plant_Crop_Mushroom_Block_Brown",
      "rotation": 2
    },
    {
      "x": -8,
      "y": 37,
      "z": 0,
      "name": "Plant_Crop_Mushroom_Block_Brown",
      "rotation": 2
    },
    {
      "x": -8,
      "y": 41,
      "z": 0,
      "name": "Plant_Crop_Mushroom_Block_Brown",
      "rotation": 2
    },
    {
      "x": -8,
      "y": 42,
      "z": 0,
      "name": "Plant_Crop_Mushroom_Block_Brown_Trunk",
      "rotation": 2
    },
    {
      "x": -8,
      "y": 43,
      "z": 0,
      "name": "Plant_Crop_Mushroom_Block_Brown_Trunk",
      "rotation": 2
    },
    {
      "x": -8,
      "y": 44,
      "z": 0,
      "name": "Plant_Crop_Mushroom_Block_Brown",
      "rotation": 2
    },
    {
      "x": -8,
      "y": 45,
      "z": 0,
      "name": "Plant_Crop_Mushroom_Block_Brown",
      "rotation": 2
    },
    {
      "x": -8,
      "y": 49,
      "z": 0,
      "name": "Plant_Crop_Mushroom_Block_Brown_Trunk",
      "rotation": 2
    },
    {
      "x": -8,
      "y": 50,
      "z": 0,
      "name": "Plant_Crop_Mushroom_Block_Brown_Trunk",
      "rotation": 2
    },
    {
      "x": -8,
      "y": 51,
      "z": 0,
      "name": "Plant_Crop_Mushroom_Block_Brown",
      "rotation": 2
    },
    {
      "x": -8,
      "y": 52,
      "z": 0,
      "name": "Plant_Crop_Mushroom_Block_Brown",
      "rotation": 2
    },
    {
      "x": -8,
      "y": 55,
      "z": 0,
      "name": "Plant_Crop_Mushroom_Block_Red",
      "rotation": 2
    },
    {
      "x": -8,
      "y": 57,
      "z": 0,
      "name": "Plant_Crop_Mushroom_Block_Brown",
      "rotation": 2
    },
    {
      "x": -8,
      "y": 58,
      "z": 0,
      "name": "Plant_Crop_Mushroom_Block_Red_Trunk",
      "rotation": 2
    },
    {
      "x": -8,
      "y": 59,
      "z": 0,
      "name": "Plant_Crop_Mushroom_Block_Red_Trunk",
      "rotation": 2
    },
    {
      "x": -8,
      "y": 60,
      "z": 0,
      "name": "Plant_Crop_Mushroom_Block_Red",
      "rotation": 2
    },
    {
      "x": -8,
      "y": 65,
      "z": 0,
      "name": "Plant_Crop_Mushroom_Block_Red_Trunk",
      "rotation": 2
    },
    {
      "x": -8,
      "y": 66,
      "z": 0,
      "name": "Plant_Crop_Mushroom_Block_Red_Trunk",
      "rotation": 2
    },
    {
      "x": -8,
      "y": 67,
      "z": 0,
      "name": "Plant_Crop_Mushroom_Block_Red",
      "rotation": 2
    },
    {
      "x": -8,
      "y": 69,
      "z": 0,
      "name": "Plant_Crop_Mushroom_Block_Brown",
      "rotation": 2
    },
    {
      "x": -8,
      "y": 72,
      "z": 0,
      "name": "Plant_Crop_Mushroom_Block_Brown",
      "rotation": 2
    },
    {
      "x": -8,
      "y": 73,
      "z": 0,
      "name": "Plant_Crop_Mushroom_Block_Brown_Trunk",
      "rotation": 2
    },
    {
      "x": -8,
      "y": 74,
      "z": 0,
      "name": "Plant_Crop_Mushroom_Block_Brown",
      "rotation": 2
    },
    {
      "x": -8,
      "y": 75,
      "z": 0,
      "name": "Plant_Crop_Mushroom_Block_Brown",
      "rotation": 2
    },
    {
      "x": -8,
      "y": 76,
      "z": 0,
      "name": "Plant_Crop_Mushroom_Block_Brown",
      "rotation": 2
    },
    {
      "x": -8,
      "y": 77,
      "z": 0,
      "name": "Plant_Crop_Mushroom_Block_Red",
      "rotation": 2
    },
    {
      "x": -8,
      "y": 78,
      "z": 0,
      "name": "Plant_Crop_Mushroom_Block_Red_Trunk",
      "rotation": 2
    },
    {
      "x": -8,
      "y": 79,
      "z": 0,
      "name": "Plant_Crop_Mushroom_Block_Red_Trunk",
      "rotation": 2
    },
    {
      "x": -8,
      "y": 80,
      "z": 0,
      "name": "Plant_Crop_Mushroom_Block_Red",
      "rotation": 2
    },
    {
      "x": -8,
      "y": 82,
      "z": 0,
      "name": "Plant_Crop_Mushroom_Block_Brown",
      "rotation": 2
    },
    {
      "x": -8,
      "y": 83,
      "z": 0,
      "name": "Plant_Crop_Mushroom_Block_Brown_Trunk",
      "rotation": 2
    },
    {
      "x": -8,
      "y": 84,
      "z": 0,
      "name": "Plant_Crop_Mushroom_Block_Brown",
      "rotation": 2
    },
    {
      "x": -8,
      "y": 85,
      "z": 0,
      "name": "Plant_Crop_Mushroom_Block_Brown",
      "rotation": 2
    },
    {
      "x": -8,
      "y": 3,
      "z": 1,
      "name": "Plant_Crop_Mushroom_Block_Red",
      "rotation": 2
    },
    {
      "x": -8,
      "y": 5,
      "z": 1,
      "name": "Plant_Crop_Mushroom_Block_Brown",
      "rotation": 2
    },
    {
      "x": -8,
      "y": 6,
      "z": 1,
      "name": "Plant_Crop_Mushroom_Block_Brown",
      "rotation": 2
    },
    {
      "x": -8,
      "y": 9,
      "z": 1,
      "name": "Plant_Crop_Mushroom_Block_Brown",
      "rotation": 2
    },
    {
      "x": -8,
      "y": 10,
      "z": 1,
      "name": "Plant_Crop_Mushroom_Block_Brown",
      "rotation": 2
    },
    {
      "x": -8,
      "y": 13,
      "z": 1,
      "name": "Plant_Crop_Mushroom_Block_Brown",
      "rotation": 2
    },
    {
      "x": -8,
      "y": 16,
      "z": 1,
      "name": "Plant_Crop_Mushroom_Block_Red",
      "rotation": 2
    },
    {
      "x": -8,
      "y": 19,
      "z": 1,
      "name": "Plant_Crop_Mushroom_Block_Red",
      "rotation": 2
    },
    {
      "x": -8,
      "y": 22,
      "z": 1,
      "name": "Plant_Crop_Mushroom_Block_Brown",
      "rotation": 2
    },
    {
      "x": -8,
      "y": 23,
      "z": 1,
      "name": "Plant_Crop_Mushroom_Block_Brown",
      "rotation": 2
    },
    {
      "x": -8,
      "y": 25,
      "z": 1,
      "name": "Plant_Crop_Mushroom_Block_Red",
      "rotation": 2
    },
    {
      "x": -8,
      "y": 26,
      "z": 1,
      "name": "Plant_Crop_Mushroom_Block_Brown",
      "rotation": 2
    },
    {
      "x": -8,
      "y": 27,
      "z": 1,
      "name": "Plant_Crop_Mushroom_Block_Red_Trunk",
      "rotation": 2
    },
    {
      "x": -8,
      "y": 28,
      "z": 1,
      "name": "Plant_Crop_Mushroom_Block_Red",
      "rotation": 2
    },
    {
      "x": -8,
      "y": 29,
      "z": 1,
      "name": "Plant_Crop_Mushroom_Block_Red",
      "rotation": 2
    },
    {
      "x": -8,
      "y": 33,
      "z": 1,
      "name": "Plant_Crop_Mushroom_Block_Brown",
      "rotation": 2
    },
    {
      "x": -8,
      "y": 34,
      "z": 1,
      "name": "Plant_Crop_Mushroom_Block_Brown",
      "rotation": 2
    },
    {
      "x": -8,
      "y": 36,
      "z": 1,
      "name": "Plant_Crop_Mushroom_Block_Brown_Trunk",
      "rotation": 2
    },
    {
      "x": -8,
      "y": 37,
      "z": 1,
      "name": "Plant_Crop_Mushroom_Block_Brown_Trunk",
      "rotation": 2
    },
    {
      "x": -8,
      "y": 38,
      "z": 1,
      "name": "Plant_Crop_Mushroom_Block_Brown",
      "rotation": 2
    },
    {
      "x": -8,
      "y": 39,
      "z": 1,
      "name": "Plant_Crop_Mushroom_Block_Red",
      "rotation": 2
    },
    {
      "x": -8,
      "y": 44,
      "z": 1,
      "name": "Plant_Crop_Mushroom_Block_Brown",
      "rotation": 2
    },
    {
      "x": -8,
      "y": 48,
      "z": 1,
      "name": "Plant_Crop_Mushroom_Block_Brown_Trunk",
      "rotation": 2
    },
    {
      "x": -8,
      "y": 49,
      "z": 1,
      "name": "Plant_Crop_Mushroom_Block_Brown_Trunk",
      "rotation": 2
    },
    {
      "x": -8,
      "y": 50,
      "z": 1,
      "name": "Plant_Crop_Mushroom_Block_Brown",
      "rotation": 2
    },
    {
      "x": -8,
      "y": 51,
      "z": 1,
      "name": "Plant_Crop_Mushroom_Block_Brown",
      "rotation": 2
    },
    {
      "x": -8,
      "y": 52,
      "z": 1,
      "name": "Plant_Crop_Mushroom_Block_Red",
      "rotation": 2
    },
    {
      "x": -8,
      "y": 54,
      "z": 1,
      "name": "Plant_Crop_Mushroom_Block_Red_Trunk",
      "rotation": 2
    },
    {
      "x": -8,
      "y": 55,
      "z": 1,
      "name": "Plant_Crop_Mushroom_Block_Red_Trunk",
      "rotation": 2
    },
    {
      "x": -8,
      "y": 56,
      "z": 1,
      "name": "Plant_Crop_Mushroom_Block_Red",
      "rotation": 2
    },
    {
      "x": -8,
      "y": 58,
      "z": 1,
      "name": "Plant_Crop_Mushroom_Block_Brown",
      "rotation": 2
    },
    {
      "x": -8,
      "y": 59,
      "z": 1,
      "name": "Plant_Crop_Mushroom_Block_Red",
      "rotation": 2
    },
    {
      "x": -8,
      "y": 60,
      "z": 1,
      "name": "Plant_Crop_Mushroom_Block_Red",
      "rotation": 2
    },
    {
      "x": -8,
      "y": 66,
      "z": 1,
      "name": "Plant_Crop_Mushroom_Block_Red",
      "rotation": 2
    },
    {
      "x": -8,
      "y": 67,
      "z": 1,
      "name": "Plant_Crop_Mushroom_Block_Brown",
      "rotation": 2
    },
    {
      "x": -8,
      "y": 70,
      "z": 1,
      "name": "Plant_Crop_Mushroom_Block_Brown_Trunk",
      "rotation": 2
    },
    {
      "x": -8,
      "y": 71,
      "z": 1,
      "name": "Plant_Crop_Mushroom_Block_Brown_Trunk",
      "rotation": 2
    },
    {
      "x": -8,
      "y": 72,
      "z": 1,
      "name": "Plant_Crop_Mushroom_Block_Brown",
      "rotation": 2
    },
    {
      "x": -8,
      "y": 73,
      "z": 1,
      "name": "Plant_Crop_Mushroom_Block_Brown",
      "rotation": 2
    },
    {
      "x": -8,
      "y": 74,
      "z": 1,
      "name": "Plant_Crop_Mushroom_Block_Brown",
      "rotation": 2
    },
    {
      "x": -8,
      "y": 75,
      "z": 1,
      "name": "Plant_Crop_Mushroom_Block_Brown",
      "rotation": 2
    },
    {
      "x": -8,
      "y": 79,
      "z": 1,
      "name": "Plant_Crop_Mushroom_Block_Brown",
      "rotation": 2
    },
    {
      "x": -8,
      "y": 80,
      "z": 1,
      "name": "Plant_Crop_Mushroom_Block_Red",
      "rotation": 2
    },
    {
      "x": -8,
      "y": 81,
      "z": 1,
      "name": "Plant_Crop_Mushroom_Block_Brown_Trunk",
      "rotation": 2
    },
    {
      "x": -8,
      "y": 82,
      "z": 1,
      "name": "Plant_Crop_Mushroom_Block_Brown",
      "rotation": 2
    },
    {
      "x": -8,
      "y": 83,
      "z": 1,
      "name": "Plant_Crop_Mushroom_Block_Brown",
      "rotation": 2
    },
    {
      "x": -8,
      "y": 84,
      "z": 1,
      "name": "Plant_Crop_Mushroom_Block_Brown",
      "rotation": 2
    },
    {
      "x": -8,
      "y": 87,
      "z": 1,
      "name": "Plant_Crop_Mushroom_Block_Red",
      "rotation": 2
    },
    {
      "x": -8,
      "y": 3,
      "z": 2,
      "name": "Plant_Crop_Mushroom_Block_Brown_Trunk",
      "rotation": 2
    },
    {
      "x": -8,
      "y": 4,
      "z": 2,
      "name": "Plant_Crop_Mushroom_Block_Brown_Trunk",
      "rotation": 2
    },
    {
      "x": -8,
      "y": 5,
      "z": 2,
      "name": "Plant_Crop_Mushroom_Block_Brown",
      "rotation": 2
    },
    {
      "x": -8,
      "y": 6,
      "z": 2,
      "name": "Plant_Crop_Mushroom_Block_Brown",
      "rotation": 2
    },
    {
      "x": -8,
      "y": 8,
      "z": 2,
      "name": "Plant_Crop_Mushroom_Block_Red",
      "rotation": 2
    },
    {
      "x": -8,
      "y": 9,
      "z": 2,
      "name": "Plant_Crop_Mushroom_Block_Brown",
      "rotation": 2
    },
    {
      "x": -8,
      "y": 19,
      "z": 2,
      "name": "Plant_Crop_Mushroom_Block_Brown_Trunk",
      "rotation": 2
    },
    {
      "x": -8,
      "y": 20,
      "z": 2,
      "name": "Plant_Crop_Mushroom_Block_Brown_Trunk",
      "rotation": 2
    },
    {
      "x": -8,
      "y": 21,
      "z": 2,
      "name": "Plant_Crop_Mushroom_Block_Brown_Trunk",
      "rotation": 2
    },
    {
      "x": -8,
      "y": 22,
      "z": 2,
      "name": "Plant_Crop_Mushroom_Block_Brown",
      "rotation": 2
    },
    {
      "x": -8,
      "y": 23,
      "z": 2,
      "name": "Plant_Crop_Mushroom_Block_Brown",
      "rotation": 2
    },
    {
      "x": -8,
      "y": 24,
      "z": 2,
      "name": "Plant_Crop_Mushroom_Block_Red_Trunk",
      "rotation": 2
    },
    {
      "x": -8,
      "y": 25,
      "z": 2,
      "name": "Plant_Crop_Mushroom_Block_Red_Trunk",
      "rotation": 2
    },
    {
      "x": -8,
      "y": 26,
      "z": 2,
      "name": "Plant_Crop_Mushroom_Block_Red",
      "rotation": 2
    },
    {
      "x": -8,
      "y": 27,
      "z": 2,
      "name": "Plant_Crop_Mushroom_Block_Red",
      "rotation": 2
    },
    {
      "x": -8,
      "y": 28,
      "z": 2,
      "name": "Plant_Crop_Mushroom_Block_Red",
      "rotation": 2
    },
    {
      "x": -8,
      "y": 31,
      "z": 2,
      "name": "Plant_Crop_Mushroom_Block_Brown_Trunk",
      "rotation": 2
    },
    {
      "x": -8,
      "y": 32,
      "z": 2,
      "name": "Plant_Crop_Mushroom_Block_Brown_Trunk",
      "rotation": 2
    },
    {
      "x": -8,
      "y": 33,
      "z": 2,
      "name": "Plant_Crop_Mushroom_Block_Brown_Trunk",
      "rotation": 2
    },
    {
      "x": -8,
      "y": 34,
      "z": 2,
      "name": "Plant_Crop_Mushroom_Block_Brown",
      "rotation": 2
    },
    {
      "x": -8,
      "y": 37,
      "z": 2,
      "name": "Plant_Crop_Mushroom_Block_Brown",
      "rotation": 2
    },
    {
      "x": -8,
      "y": 38,
      "z": 2,
      "name": "Plant_Crop_Mushroom_Block_Red_Trunk",
      "rotation": 2
    },
    {
      "x": -8,
      "y": 39,
      "z": 2,
      "name": "Plant_Crop_Mushroom_Block_Red_Trunk",
      "rotation": 2
    },
    {
      "x": -8,
      "y": 40,
      "z": 2,
      "name": "Plant_Crop_Mushroom_Block_Red",
      "rotation": 2
    },
    {
      "x": -8,
      "y": 46,
      "z": 2,
      "name": "Plant_Crop_Mushroom_Block_Red",
      "rotation": 2
    },
    {
      "x": -8,
      "y": 50,
      "z": 2,
      "name": "Plant_Crop_Mushroom_Block_Brown",
      "rotation": 2
    },
    {
      "x": -8,
      "y": 51,
      "z": 2,
      "name": "Plant_Crop_Mushroom_Block_Red_Trunk",
      "rotation": 2
    },
    {
      "x": -8,
      "y": 52,
      "z": 2,
      "name": "Plant_Crop_Mushroom_Block_Red_Trunk",
      "rotation": 2
    },
    {
      "x": -8,
      "y": 53,
      "z": 2,
      "name": "Plant_Crop_Mushroom_Block_Red",
      "rotation": 2
    },
    {
      "x": -8,
      "y": 55,
      "z": 2,
      "name": "Plant_Crop_Mushroom_Block_Red",
      "rotation": 2
    },
    {
      "x": -8,
      "y": 56,
      "z": 2,
      "name": "Plant_Crop_Mushroom_Block_Brown_Trunk",
      "rotation": 2
    },
    {
      "x": -8,
      "y": 57,
      "z": 2,
      "name": "Plant_Crop_Mushroom_Block_Brown_Trunk",
      "rotation": 2
    },
    {
      "x": -8,
      "y": 58,
      "z": 2,
      "name": "Plant_Crop_Mushroom_Block_Brown",
      "rotation": 2
    },
    {
      "x": -8,
      "y": 59,
      "z": 2,
      "name": "Plant_Crop_Mushroom_Block_Brown",
      "rotation": 2
    },
    {
      "x": -8,
      "y": 63,
      "z": 2,
      "name": "Plant_Crop_Mushroom_Block_Red",
      "rotation": 2
    },
    {
      "x": -8,
      "y": 65,
      "z": 2,
      "name": "Plant_Crop_Mushroom_Block_Brown_Trunk",
      "rotation": 2
    },
    {
      "x": -8,
      "y": 66,
      "z": 2,
      "name": "Plant_Crop_Mushroom_Block_Brown_Trunk",
      "rotation": 2
    },
    {
      "x": -8,
      "y": 67,
      "z": 2,
      "name": "Plant_Crop_Mushroom_Block_Brown",
      "rotation": 2
    },
    {
      "x": -8,
      "y": 68,
      "z": 2,
      "name": "Plant_Crop_Mushroom_Block_Brown",
      "rotation": 2
    },
    {
      "x": -8,
      "y": 69,
      "z": 2,
      "name": "Plant_Crop_Mushroom_Block_Red",
      "rotation": 2
    },
    {
      "x": -8,
      "y": 72,
      "z": 2,
      "name": "Plant_Crop_Mushroom_Block_Brown",
      "rotation": 2
    },
    {
      "x": -8,
      "y": 74,
      "z": 2,
      "name": "Plant_Crop_Mushroom_Block_Red",
      "rotation": 2
    },
    {
      "x": -8,
      "y": 75,
      "z": 2,
      "name": "Plant_Crop_Mushroom_Block_Red",
      "rotation": 2
    },
    {
      "x": -8,
      "y": 77,
      "z": 2,
      "name": "Plant_Crop_Mushroom_Block_Brown_Trunk",
      "rotation": 2
    },
    {
      "x": -8,
      "y": 78,
      "z": 2,
      "name": "Plant_Crop_Mushroom_Block_Brown_Trunk",
      "rotation": 2
    },
    {
      "x": -8,
      "y": 79,
      "z": 2,
      "name": "Plant_Crop_Mushroom_Block_Brown",
      "rotation": 2
    },
    {
      "x": -8,
      "y": 80,
      "z": 2,
      "name": "Plant_Crop_Mushroom_Block_Brown",
      "rotation": 2
    },
    {
      "x": -8,
      "y": 81,
      "z": 2,
      "name": "Plant_Crop_Mushroom_Block_Red",
      "rotation": 2
    },
    {
      "x": -8,
      "y": 82,
      "z": 2,
      "name": "Plant_Crop_Mushroom_Block_Brown",
      "rotation": 2
    },
    {
      "x": -8,
      "y": 84,
      "z": 2,
      "name": "Plant_Crop_Mushroom_Block_Red_Trunk",
      "rotation": 2
    },
    {
      "x": -8,
      "y": 85,
      "z": 2,
      "name": "Plant_Crop_Mushroom_Block_Red_Trunk",
      "rotation": 2
    },
    {
      "x": -8,
      "y": 86,
      "z": 2,
      "name": "Plant_Crop_Mushroom_Block_Red",
      "rotation": 2
    },
    {
      "x": -8,
      "y": 87,
      "z": 2,
      "name": "Plant_Crop_Mushroom_Block_Red",
      "rotation": 2
    },
    {
      "x": -8,
      "y": 88,
      "z": 2,
      "name": "Plant_Crop_Mushroom_Block_Red",
      "rotation": 2
    },
    {
      "x": -8,
      "y": 5,
      "z": 3,
      "name": "Plant_Crop_Mushroom_Block_Brown",
      "rotation": 2
    },
    {
      "x": -8,
      "y": 6,
      "z": 3,
      "name": "Plant_Crop_Mushroom_Block_Brown",
      "rotation": 2
    },
    {
      "x": -8,
      "y": 8,
      "z": 3,
      "name": "Plant_Crop_Mushroom_Block_Red",
      "rotation": 2
    },
    {
      "x": -8,
      "y": 16,
      "z": 3,
      "name": "Plant_Crop_Mushroom_Block_Brown",
      "rotation": 2
    },
    {
      "x": -8,
      "y": 18,
      "z": 3,
      "name": "Plant_Crop_Mushroom_Block_Red",
      "rotation": 2
    },
    {
      "x": -8,
      "y": 22,
      "z": 3,
      "name": "Plant_Crop_Mushroom_Block_Brown",
      "rotation": 2
    },
    {
      "x": -8,
      "y": 23,
      "z": 3,
      "name": "Plant_Crop_Mushroom_Block_Brown",
      "rotation": 2
    },
    {
      "x": -8,
      "y": 25,
      "z": 3,
      "name": "Plant_Crop_Mushroom_Block_Red",
      "rotation": 2
    },
    {
      "x": -8,
      "y": 27,
      "z": 3,
      "name": "Plant_Crop_Mushroom_Block_Red",
      "rotation": 2
    },
    {
      "x": -8,
      "y": 33,
      "z": 3,
      "name": "Plant_Crop_Mushroom_Block_Brown",
      "rotation": 2
    },
    {
      "x": -8,
      "y": 39,
      "z": 3,
      "name": "Plant_Crop_Mushroom_Block_Red",
      "rotation": 2
    },
    {
      "x": -8,
      "y": 46,
      "z": 3,
      "name": "Plant_Crop_Mushroom_Block_Red",
      "rotation": 2
    },
    {
      "x": -8,
      "y": 52,
      "z": 3,
      "name": "Plant_Crop_Mushroom_Block_Red",
      "rotation": 2
    },
    {
      "x": -8,
      "y": 58,
      "z": 3,
      "name": "Plant_Crop_Mushroom_Block_Brown",
      "rotation": 2
    },
    {
      "x": -8,
      "y": 62,
      "z": 3,
      "name": "Plant_Crop_Mushroom_Block_Red_Trunk",
      "rotation": 2
    },
    {
      "x": -8,
      "y": 63,
      "z": 3,
      "name": "Plant_Crop_Mushroom_Block_Red",
      "rotation": 2
    },
    {
      "x": -8,
      "y": 67,
      "z": 3,
      "name": "Plant_Crop_Mushroom_Block_Brown",
      "rotation": 2
    },
    {
      "x": -8,
      "y": 69,
      "z": 3,
      "name": "Plant_Crop_Mushroom_Block_Red",
      "rotation": 2
    },
    {
      "x": -8,
      "y": 74,
      "z": 3,
      "name": "Plant_Crop_Mushroom_Block_Red_Trunk",
      "rotation": 2
    },
    {
      "x": -8,
      "y": 75,
      "z": 3,
      "name": "Plant_Crop_Mushroom_Block_Red",
      "rotation": 2
    },
    {
      "x": -8,
      "y": 79,
      "z": 3,
      "name": "Plant_Crop_Mushroom_Block_Brown",
      "rotation": 2
    },
    {
      "x": -8,
      "y": 81,
      "z": 3,
      "name": "Plant_Crop_Mushroom_Block_Red",
      "rotation": 2
    },
    {
      "x": -8,
      "y": 87,
      "z": 3,
      "name": "Plant_Crop_Mushroom_Block_Red",
      "rotation": 2
    },
    {
      "x": -8,
      "y": 16,
      "z": 4,
      "name": "Plant_Crop_Mushroom_Block_Brown",
      "rotation": 2
    },
    {
      "x": -8,
      "y": 22,
      "z": 4,
      "name": "Plant_Crop_Mushroom_Block_Brown",
      "rotation": 2
    },
    {
      "x": -8,
      "y": 23,
      "z": 4,
      "name": "Plant_Crop_Mushroom_Block_Brown",
      "rotation": 2
    },
    {
      "x": -8,
      "y": 27,
      "z": 4,
      "name": "Plant_Crop_Mushroom_Block_Red",
      "rotation": 2
    },
    {
      "x": -8,
      "y": 63,
      "z": 4,
      "name": "Plant_Crop_Mushroom_Block_Red",
      "rotation": 2
    },
    {
      "x": -8,
      "y": 74,
      "z": 4,
      "name": "Plant_Crop_Mushroom_Block_Red",
      "rotation": 2
    },
    {
      "x": -7,
      "y": 18,
      "z": -6,
      "name": "Plant_Crop_Mushroom_Block_Brown"
    },
    {
      "x": -7,
      "y": 22,
      "z": -6,
      "name": "Plant_Crop_Mushroom_Block_Red"
    },
    {
      "x": -7,
      "y": 27,
      "z": -6,
      "name": "Plant_Crop_Mushroom_Block_Red"
    },
    {
      "x": -7,
      "y": 29,
      "z": -6,
      "name": "Plant_Crop_Mushroom_Block_Brown"
    },
    {
      "x": -7,
      "y": 45,
      "z": -6,
      "name": "Plant_Crop_Mushroom_Block_Brown"
    },
    {
      "x": -7,
      "y": 68,
      "z": -6,
      "name": "Plant_Crop_Mushroom_Block_Red"
    },
    {
      "x": -7,
      "y": 71,
      "z": -6,
      "name": "Plant_Crop_Mushroom_Block_Brown"
    },
    {
      "x": -7,
      "y": 72,
      "z": -6,
      "name": "Plant_Crop_Mushroom_Block_Brown"
    },
    {
      "x": -7,
      "y": 76,
      "z": -6,
      "name": "Plant_Crop_Mushroom_Block_Red"
    },
    {
      "x": -7,
      "y": 79,
      "z": -6,
      "name": "Plant_Crop_Mushroom_Block_Red"
    },
    {
      "x": -7,
      "y": 4,
      "z": -5,
      "name": "Plant_Crop_Mushroom_Block_Brown"
    },
    {
      "x": -7,
      "y": 6,
      "z": -5,
      "name": "Plant_Crop_Mushroom_Block_Red"
    },
    {
      "x": -7,
      "y": 12,
      "z": -5,
      "name": "Plant_Crop_Mushroom_Block_Brown"
    },
    {
      "x": -7,
      "y": 15,
      "z": -5,
      "name": "Plant_Crop_Mushroom_Block_Brown"
    },
    {
      "x": -7,
      "y": 17,
      "z": -5,
      "name": "Plant_Crop_Mushroom_Block_Brown_Trunk"
    },
    {
      "x": -7,
      "y": 18,
      "z": -5,
      "name": "Plant_Crop_Mushroom_Block_Brown"
    },
    {
      "x": -7,
      "y": 19,
      "z": -5,
      "name": "Plant_Crop_Mushroom_Block_Brown"
    },
    {
      "x": -7,
      "y": 21,
      "z": -5,
      "name": "Plant_Crop_Mushroom_Block_Red_Trunk"
    },
    {
      "x": -7,
      "y": 22,
      "z": -5,
      "name": "Plant_Crop_Mushroom_Block_Red"
    },
    {
      "x": -7,
      "y": 23,
      "z": -5,
      "name": "Plant_Crop_Mushroom_Block_Red"
    },
    {
      "x": -7,
      "y": 24,
      "z": -5,
      "name": "Plant_Crop_Mushroom_Block_Brown"
    },
    {
      "x": -7,
      "y": 27,
      "z": -5,
      "name": "Plant_Crop_Mushroom_Block_Red"
    },
    {
      "x": -7,
      "y": 32,
      "z": -5,
      "name": "Plant_Crop_Mushroom_Block_Brown"
    },
    {
      "x": -7,
      "y": 39,
      "z": -5,
      "name": "Plant_Crop_Mushroom_Block_Red"
    },
    {
      "x": -7,
      "y": 45,
      "z": -5,
      "name": "Plant_Crop_Mushroom_Block_Brown"
    },
    {
      "x": -7,
      "y": 49,
      "z": -5,
      "name": "Plant_Crop_Mushroom_Block_Red"
    },
    {
      "x": -7,
      "y": 54,
      "z": -5,
      "name": "Plant_Crop_Mushroom_Block_Red"
    },
    {
      "x": -7,
      "y": 56,
      "z": -5,
      "name": "Plant_Crop_Mushroom_Block_Brown"
    },
    {
      "x": -7,
      "y": 62,
      "z": -5,
      "name": "Plant_Crop_Mushroom_Block_Red"
    },
    {
      "x": -7,
      "y": 68,
      "z": -5,
      "name": "Plant_Crop_Mushroom_Block_Red"
    },
    {
      "x": -7,
      "y": 71,
      "z": -5,
      "name": "Plant_Crop_Mushroom_Block_Brown"
    },
    {
      "x": -7,
      "y": 75,
      "z": -5,
      "name": "Plant_Crop_Mushroom_Block_Red_Trunk"
    },
    {
      "x": -7,
      "y": 76,
      "z": -5,
      "name": "Plant_Crop_Mushroom_Block_Red"
    },
    {
      "x": -7,
      "y": 77,
      "z": -5,
      "name": "Plant_Crop_Mushroom_Block_Red"
    },
    {
      "x": -7,
      "y": 79,
      "z": -5,
      "name": "Plant_Crop_Mushroom_Block_Red_Trunk"
    },
    {
      "x": -7,
      "y": 80,
      "z": -5,
      "name": "Plant_Crop_Mushroom_Block_Red"
    },
    {
      "x": -7,
      "y": 82,
      "z": -5,
      "name": "Plant_Crop_Mushroom_Block_Brown"
    },
    {
      "x": -7,
      "y": 85,
      "z": -5,
      "name": "Plant_Crop_Mushroom_Block_Red"
    },
    {
      "x": -7,
      "y": 86,
      "z": -5,
      "name": "Plant_Crop_Mushroom_Block_Brown"
    },
    {
      "x": -7,
      "y": 3,
      "z": -4,
      "name": "Plant_Crop_Mushroom_Block_Brown_Trunk"
    },
    {
      "x": -7,
      "y": 4,
      "z": -4,
      "name": "Plant_Crop_Mushroom_Block_Brown_Trunk"
    },
    {
      "x": -7,
      "y": 5,
      "z": -4,
      "name": "Plant_Crop_Mushroom_Block_Brown"
    },
    {
      "x": -7,
      "y": 6,
      "z": -4,
      "name": "Plant_Crop_Mushroom_Block_Red"
    },
    {
      "x": -7,
      "y": 8,
      "z": -4,
      "name": "Plant_Crop_Mushroom_Block_Brown"
    },
    {
      "x": -7,
      "y": 12,
      "z": -4,
      "name": "Plant_Crop_Mushroom_Block_Brown"
    },
    {
      "x": -7,
      "y": 14,
      "z": -4,
      "name": "Plant_Crop_Mushroom_Block_Brown_Trunk"
    },
    {
      "x": -7,
      "y": 15,
      "z": -4,
      "name": "Plant_Crop_Mushroom_Block_Brown_Trunk"
    },
    {
      "x": -7,
      "y": 16,
      "z": -4,
      "name": "Plant_Crop_Mushroom_Block_Brown"
    },
    {
      "x": -7,
      "y": 18,
      "z": -4,
      "name": "Plant_Crop_Mushroom_Block_Brown"
    },
    {
      "x": -7,
      "y": 22,
      "z": -4,
      "name": "Plant_Crop_Mushroom_Block_Red"
    },
    {
      "x": -7,
      "y": 23,
      "z": -4,
      "name": "Plant_Crop_Mushroom_Block_Brown_Trunk"
    },
    {
      "x": -7,
      "y": 24,
      "z": -4,
      "name": "Plant_Crop_Mushroom_Block_Brown"
    },
    {
      "x": -7,
      "y": 25,
      "z": -4,
      "name": "Plant_Crop_Mushroom_Block_Brown"
    },
    {
      "x": -7,
      "y": 27,
      "z": -4,
      "name": "Plant_Crop_Mushroom_Block_Red"
    },
    {
      "x": -7,
      "y": 32,
      "z": -4,
      "name": "Plant_Crop_Mushroom_Block_Brown"
    },
    {
      "x": -7,
      "y": 35,
      "z": -4,
      "name": "Plant_Crop_Mushroom_Block_Brown"
    },
    {
      "x": -7,
      "y": 38,
      "z": -4,
      "name": "Plant_Crop_Mushroom_Block_Red_Trunk"
    },
    {
      "x": -7,
      "y": 39,
      "z": -4,
      "name": "Plant_Crop_Mushroom_Block_Red_Trunk"
    },
    {
      "x": -7,
      "y": 40,
      "z": -4,
      "name": "Plant_Crop_Mushroom_Block_Red"
    },
    {
      "x": -7,
      "y": 42,
      "z": -4,
      "name": "Plant_Crop_Mushroom_Block_Red",
      "rotation": 2
    },
    {
      "x": -7,
      "y": 49,
      "z": -4,
      "name": "Plant_Crop_Mushroom_Block_Red"
    },
    {
      "x": -7,
      "y": 52,
      "z": -4,
      "name": "Plant_Crop_Mushroom_Block_Red_Trunk"
    },
    {
      "x": -7,
      "y": 53,
      "z": -4,
      "name": "Plant_Crop_Mushroom_Block_Red_Trunk"
    },
    {
      "x": -7,
      "y": 54,
      "z": -4,
      "name": "Plant_Crop_Mushroom_Block_Red"
    },
    {
      "x": -7,
      "y": 55,
      "z": -4,
      "name": "Plant_Crop_Mushroom_Block_Red"
    },
    {
      "x": -7,
      "y": 56,
      "z": -4,
      "name": "Plant_Crop_Mushroom_Block_Brown"
    },
    {
      "x": -7,
      "y": 60,
      "z": -4,
      "name": "Plant_Crop_Mushroom_Block_Red_Trunk"
    },
    {
      "x": -7,
      "y": 61,
      "z": -4,
      "name": "Plant_Crop_Mushroom_Block_Red_Trunk"
    },
    {
      "x": -7,
      "y": 62,
      "z": -4,
      "name": "Plant_Crop_Mushroom_Block_Red_Trunk"
    },
    {
      "x": -7,
      "y": 63,
      "z": -4,
      "name": "Plant_Crop_Mushroom_Block_Red"
    },
    {
      "x": -7,
      "y": 67,
      "z": -4,
      "name": "Plant_Crop_Mushroom_Block_Brown"
    },
    {
      "x": -7,
      "y": 68,
      "z": -4,
      "name": "Plant_Crop_Mushroom_Block_Red"
    },
    {
      "x": -7,
      "y": 71,
      "z": -4,
      "name": "Plant_Crop_Mushroom_Block_Brown"
    },
    {
      "x": -7,
      "y": 74,
      "z": -4,
      "name": "Plant_Crop_Mushroom_Block_Red_Trunk"
    },
    {
      "x": -7,
      "y": 75,
      "z": -4,
      "name": "Plant_Crop_Mushroom_Block_Red_Trunk"
    },
    {
      "x": -7,
      "y": 76,
      "z": -4,
      "name": "Plant_Crop_Mushroom_Block_Red"
    },
    {
      "x": -7,
      "y": 77,
      "z": -4,
      "name": "Plant_Crop_Mushroom_Block_Red"
    },
    {
      "x": -7,
      "y": 79,
      "z": -4,
      "name": "Plant_Crop_Mushroom_Block_Red"
    },
    {
      "x": -7,
      "y": 85,
      "z": -4,
      "name": "Plant_Crop_Mushroom_Block_Brown_Trunk"
    },
    {
      "x": -7,
      "y": 86,
      "z": -4,
      "name": "Plant_Crop_Mushroom_Block_Brown_Trunk"
    },
    {
      "x": -7,
      "y": 87,
      "z": -4,
      "name": "Plant_Crop_Mushroom_Block_Brown"
    },
    {
      "x": -7,
      "y": 4,
      "z": -3,
      "name": "Plant_Crop_Mushroom_Block_Brown"
    },
    {
      "x": -7,
      "y": 7,
      "z": -3,
      "name": "Plant_Crop_Mushroom_Block_Brown_Trunk"
    },
    {
      "x": -7,
      "y": 8,
      "z": -3,
      "name": "Plant_Crop_Mushroom_Block_Brown_Trunk"
    },
    {
      "x": -7,
      "y": 9,
      "z": -3,
      "name": "Plant_Crop_Mushroom_Block_Brown"
    },
    {
      "x": -7,
      "y": 10,
      "z": -3,
      "name": "Plant_Crop_Mushroom_Block_Red_Trunk"
    },
    {
      "x": -7,
      "y": 11,
      "z": -3,
      "name": "Plant_Crop_Mushroom_Block_Red_Trunk"
    },
    {
      "x": -7,
      "y": 12,
      "z": -3,
      "name": "Plant_Crop_Mushroom_Block_Red"
    },
    {
      "x": -7,
      "y": 13,
      "z": -3,
      "name": "Plant_Crop_Mushroom_Block_Red"
    },
    {
      "x": -7,
      "y": 15,
      "z": -3,
      "name": "Plant_Crop_Mushroom_Block_Brown"
    },
    {
      "x": -7,
      "y": 21,
      "z": -3,
      "name": "Plant_Crop_Mushroom_Block_Brown_Trunk"
    },
    {
      "x": -7,
      "y": 22,
      "z": -3,
      "name": "Plant_Crop_Mushroom_Block_Brown_Trunk"
    },
    {
      "x": -7,
      "y": 23,
      "z": -3,
      "name": "Plant_Crop_Mushroom_Block_Brown_Trunk"
    },
    {
      "x": -7,
      "y": 24,
      "z": -3,
      "name": "Plant_Crop_Mushroom_Block_Brown"
    },
    {
      "x": -7,
      "y": 25,
      "z": -3,
      "name": "Plant_Crop_Mushroom_Block_Brown"
    },
    {
      "x": -7,
      "y": 31,
      "z": -3,
      "name": "Plant_Crop_Mushroom_Block_Red",
      "rotation": 2
    },
    {
      "x": -7,
      "y": 34,
      "z": -3,
      "name": "Plant_Crop_Mushroom_Block_Brown_Trunk"
    },
    {
      "x": -7,
      "y": 35,
      "z": -3,
      "name": "Plant_Crop_Mushroom_Block_Brown_Trunk"
    },
    {
      "x": -7,
      "y": 36,
      "z": -3,
      "name": "Plant_Crop_Mushroom_Block_Brown"
    },
    {
      "x": -7,
      "y": 39,
      "z": -3,
      "name": "Plant_Crop_Mushroom_Block_Red"
    },
    {
      "x": -7,
      "y": 40,
      "z": -3,
      "name": "Plant_Crop_Mushroom_Block_Red_Trunk",
      "rotation": 2
    },
    {
      "x": -7,
      "y": 41,
      "z": -3,
      "name": "Plant_Crop_Mushroom_Block_Red_Trunk",
      "rotation": 2
    },
    {
      "x": -7,
      "y": 42,
      "z": -3,
      "name": "Plant_Crop_Mushroom_Block_Red",
      "rotation": 2
    },
    {
      "x": -7,
      "y": 43,
      "z": -3,
      "name": "Plant_Crop_Mushroom_Block_Red",
      "rotation": 2
    },
    {
      "x": -7,
      "y": 44,
      "z": -3,
      "name": "Plant_Crop_Mushroom_Block_Red",
      "rotation": 2
    },
    {
      "x": -7,
      "y": 47,
      "z": -3,
      "name": "Plant_Crop_Mushroom_Block_Brown",
      "rotation": 2
    },
    {
      "x": -7,
      "y": 50,
      "z": -3,
      "name": "Plant_Crop_Mushroom_Block_Brown_Trunk"
    },
    {
      "x": -7,
      "y": 51,
      "z": -3,
      "name": "Plant_Crop_Mushroom_Block_Brown_Trunk"
    },
    {
      "x": -7,
      "y": 53,
      "z": -3,
      "name": "Plant_Crop_Mushroom_Block_Red",
      "rotation": 2
    },
    {
      "x": -7,
      "y": 54,
      "z": -3,
      "name": "Plant_Crop_Mushroom_Block_Red"
    },
    {
      "x": -7,
      "y": 62,
      "z": -3,
      "name": "Plant_Crop_Mushroom_Block_Red"
    },
    {
      "x": -7,
      "y": 64,
      "z": -3,
      "name": "Plant_Crop_Mushroom_Block_Brown",
      "rotation": 2
    },
    {
      "x": -7,
      "y": 65,
      "z": -3,
      "name": "Plant_Crop_Mushroom_Block_Brown_Trunk"
    },
    {
      "x": -7,
      "y": 66,
      "z": -3,
      "name": "Plant_Crop_Mushroom_Block_Brown_Trunk"
    },
    {
      "x": -7,
      "y": 67,
      "z": -3,
      "name": "Plant_Crop_Mushroom_Block_Brown_Trunk"
    },
    {
      "x": -7,
      "y": 68,
      "z": -3,
      "name": "Plant_Crop_Mushroom_Block_Brown"
    },
    {
      "x": -7,
      "y": 74,
      "z": -3,
      "name": "Plant_Crop_Mushroom_Block_Brown",
      "rotation": 2
    },
    {
      "x": -7,
      "y": 75,
      "z": -3,
      "name": "Plant_Crop_Mushroom_Block_Brown",
      "rotation": 2
    },
    {
      "x": -7,
      "y": 76,
      "z": -3,
      "name": "Plant_Crop_Mushroom_Block_Red"
    },
    {
      "x": -7,
      "y": 80,
      "z": -3,
      "name": "Plant_Crop_Mushroom_Block_Brown",
      "rotation": 2
    },
    {
      "x": -7,
      "y": 81,
      "z": -3,
      "name": "Plant_Crop_Mushroom_Block_Brown",
      "rotation": 2
    },
    {
      "x": -7,
      "y": 0,
      "z": -2,
      "name": "Rock_Basalt_Brick",
      "rotation": 2
    },
    {
      "x": -7,
      "y": 1,
      "z": -2,
      "name": "Rock_Basalt_Brick",
      "rotation": 2
    },
    {
      "x": -7,
      "y": 2,
      "z": -2,
      "name": "Rock_Basalt_Brick",
      "rotation": 2
    },
    {
      "x": -7,
      "y": 3,
      "z": -2,
      "name": "Rock_Basalt_Brick",
      "rotation": 2
    },
    {
      "x": -7,
      "y": 4,
      "z": -2,
      "name": "Rock_Basalt_Brick",
      "rotation": 2
    },
    {
      "x": -7,
      "y": 5,
      "z": -2,
      "name": "Rock_Basalt_Brick",
      "rotation": 2
    },
    {
      "x": -7,
      "y": 6,
      "z": -2,
      "name": "Rock_Basalt_Brick",
      "rotation": 2
    },
    {
      "x": -7,
      "y": 7,
      "z": -2,
      "name": "Rock_Basalt_Brick",
      "rotation": 2
    },
    {
      "x": -7,
      "y": 8,
      "z": -2,
      "name": "Rock_Basalt_Brick",
      "rotation": 2
    },
    {
      "x": -7,
      "y": 9,
      "z": -2,
      "name": "Rock_Basalt_Brick",
      "rotation": 2
    },
    {
      "x": -7,
      "y": 10,
      "z": -2,
      "name": "Rock_Basalt_Brick",
      "rotation": 2
    },
    {
      "x": -7,
      "y": 11,
      "z": -2,
      "name": "Rock_Basalt_Brick",
      "rotation": 2
    },
    {
      "x": -7,
      "y": 12,
      "z": -2,
      "name": "Rock_Basalt_Brick",
      "rotation": 2
    },
    {
      "x": -7,
      "y": 13,
      "z": -2,
      "name": "Rock_Basalt_Brick",
      "rotation": 2
    },
    {
      "x": -7,
      "y": 14,
      "z": -2,
      "name": "Rock_Basalt_Brick",
      "rotation": 2
    },
    {
      "x": -7,
      "y": 15,
      "z": -2,
      "name": "Rock_Basalt_Brick",
      "rotation": 2
    },
    {
      "x": -7,
      "y": 16,
      "z": -2,
      "name": "Rock_Basalt_Brick",
      "rotation": 2
    },
    {
      "x": -7,
      "y": 17,
      "z": -2,
      "name": "Rock_Basalt_Brick",
      "rotation": 2
    },
    {
      "x": -7,
      "y": 18,
      "z": -2,
      "name": "Rock_Basalt_Brick",
      "rotation": 2
    },
    {
      "x": -7,
      "y": 19,
      "z": -2,
      "name": "Rock_Basalt_Brick",
      "rotation": 2
    },
    {
      "x": -7,
      "y": 20,
      "z": -2,
      "name": "Rock_Basalt_Brick",
      "rotation": 2
    },
    {
      "x": -7,
      "y": 21,
      "z": -2,
      "name": "Rock_Basalt_Brick",
      "rotation": 2
    },
    {
      "x": -7,
      "y": 22,
      "z": -2,
      "name": "Rock_Basalt_Brick",
      "rotation": 2
    },
    {
      "x": -7,
      "y": 23,
      "z": -2,
      "name": "Rock_Basalt_Brick",
      "rotation": 2
    },
    {
      "x": -7,
      "y": 24,
      "z": -2,
      "name": "Rock_Basalt_Brick",
      "rotation": 2
    },
    {
      "x": -7,
      "y": 25,
      "z": -2,
      "name": "Rock_Basalt_Brick",
      "rotation": 2
    },
    {
      "x": -7,
      "y": 26,
      "z": -2,
      "name": "Rock_Basalt_Brick",
      "rotation": 2
    },
    {
      "x": -7,
      "y": 27,
      "z": -2,
      "name": "Rock_Basalt_Brick",
      "rotation": 2
    },
    {
      "x": -7,
      "y": 28,
      "z": -2,
      "name": "Rock_Basalt_Brick",
      "rotation": 2
    },
    {
      "x": -7,
      "y": 29,
      "z": -2,
      "name": "Rock_Basalt_Brick",
      "rotation": 2
    },
    {
      "x": -7,
      "y": 30,
      "z": -2,
      "name": "Rock_Basalt_Brick",
      "rotation": 2
    },
    {
      "x": -7,
      "y": 31,
      "z": -2,
      "name": "Rock_Basalt_Brick",
      "rotation": 2
    },
    {
      "x": -7,
      "y": 32,
      "z": -2,
      "name": "Rock_Basalt_Brick",
      "rotation": 2
    },
    {
      "x": -7,
      "y": 33,
      "z": -2,
      "name": "Rock_Basalt_Brick",
      "rotation": 2
    },
    {
      "x": -7,
      "y": 34,
      "z": -2,
      "name": "Rock_Basalt_Brick",
      "rotation": 2
    },
    {
      "x": -7,
      "y": 35,
      "z": -2,
      "name": "Rock_Basalt_Brick",
      "rotation": 2
    },
    {
      "x": -7,
      "y": 36,
      "z": -2,
      "name": "Rock_Basalt_Brick",
      "rotation": 2
    },
    {
      "x": -7,
      "y": 37,
      "z": -2,
      "name": "Rock_Basalt_Brick",
      "rotation": 2
    },
    {
      "x": -7,
      "y": 38,
      "z": -2,
      "name": "Rock_Basalt_Brick",
      "rotation": 2
    },
    {
      "x": -7,
      "y": 39,
      "z": -2,
      "name": "Rock_Basalt_Brick",
      "rotation": 2
    },
    {
      "x": -7,
      "y": 40,
      "z": -2,
      "name": "Rock_Basalt_Brick",
      "rotation": 2
    },
    {
      "x": -7,
      "y": 41,
      "z": -2,
      "name": "Rock_Basalt_Brick",
      "rotation": 2
    },
    {
      "x": -7,
      "y": 42,
      "z": -2,
      "name": "Rock_Basalt_Brick",
      "rotation": 2
    },
    {
      "x": -7,
      "y": 43,
      "z": -2,
      "name": "Rock_Basalt_Brick",
      "rotation": 2
    },
    {
      "x": -7,
      "y": 44,
      "z": -2,
      "name": "Rock_Basalt_Brick",
      "rotation": 2
    },
    {
      "x": -7,
      "y": 45,
      "z": -2,
      "name": "Rock_Basalt_Brick",
      "rotation": 2
    },
    {
      "x": -7,
      "y": 46,
      "z": -2,
      "name": "Rock_Basalt_Brick",
      "rotation": 2
    },
    {
      "x": -7,
      "y": 47,
      "z": -2,
      "name": "Rock_Basalt_Brick",
      "rotation": 2
    },
    {
      "x": -7,
      "y": 48,
      "z": -2,
      "name": "Rock_Basalt_Brick",
      "rotation": 2
    },
    {
      "x": -7,
      "y": 49,
      "z": -2,
      "name": "Rock_Basalt_Brick",
      "rotation": 2
    },
    {
      "x": -7,
      "y": 50,
      "z": -2,
      "name": "Rock_Basalt_Brick",
      "rotation": 2
    },
    {
      "x": -7,
      "y": 51,
      "z": -2,
      "name": "Rock_Basalt_Brick",
      "rotation": 2
    },
    {
      "x": -7,
      "y": 52,
      "z": -2,
      "name": "Rock_Basalt_Brick",
      "rotation": 2
    },
    {
      "x": -7,
      "y": 53,
      "z": -2,
      "name": "Rock_Basalt_Brick",
      "rotation": 2
    },
    {
      "x": -7,
      "y": 54,
      "z": -2,
      "name": "Rock_Basalt_Brick",
      "rotation": 2
    },
    {
      "x": -7,
      "y": 55,
      "z": -2,
      "name": "Rock_Basalt_Brick",
      "rotation": 2
    },
    {
      "x": -7,
      "y": 56,
      "z": -2,
      "name": "Rock_Basalt_Brick",
      "rotation": 2
    },
    {
      "x": -7,
      "y": 57,
      "z": -2,
      "name": "Rock_Basalt_Brick",
      "rotation": 2
    },
    {
      "x": -7,
      "y": 58,
      "z": -2,
      "name": "Rock_Basalt_Brick",
      "rotation": 2
    },
    {
      "x": -7,
      "y": 59,
      "z": -2,
      "name": "Rock_Basalt_Brick",
      "rotation": 2
    },
    {
      "x": -7,
      "y": 60,
      "z": -2,
      "name": "Rock_Basalt_Brick",
      "rotation": 2
    },
    {
      "x": -7,
      "y": 61,
      "z": -2,
      "name": "Rock_Basalt_Brick",
      "rotation": 2
    },
    {
      "x": -7,
      "y": 62,
      "z": -2,
      "name": "Rock_Basalt_Brick",
      "rotation": 2
    },
    {
      "x": -7,
      "y": 63,
      "z": -2,
      "name": "Rock_Basalt_Brick",
      "rotation": 2
    },
    {
      "x": -7,
      "y": 64,
      "z": -2,
      "name": "Rock_Basalt_Brick",
      "rotation": 2
    },
    {
      "x": -7,
      "y": 65,
      "z": -2,
      "name": "Rock_Basalt_Brick",
      "rotation": 2
    },
    {
      "x": -7,
      "y": 66,
      "z": -2,
      "name": "Rock_Basalt_Brick",
      "rotation": 2
    },
    {
      "x": -7,
      "y": 67,
      "z": -2,
      "name": "Rock_Basalt_Brick",
      "rotation": 2
    },
    {
      "x": -7,
      "y": 68,
      "z": -2,
      "name": "Rock_Basalt_Brick",
      "rotation": 2
    },
    {
      "x": -7,
      "y": 69,
      "z": -2,
      "name": "Rock_Basalt_Brick",
      "rotation": 2
    },
    {
      "x": -7,
      "y": 70,
      "z": -2,
      "name": "Rock_Basalt_Brick",
      "rotation": 2
    },
    {
      "x": -7,
      "y": 71,
      "z": -2,
      "name": "Rock_Basalt_Brick",
      "rotation": 2
    },
    {
      "x": -7,
      "y": 72,
      "z": -2,
      "name": "Rock_Basalt_Brick",
      "rotation": 2
    },
    {
      "x": -7,
      "y": 73,
      "z": -2,
      "name": "Rock_Basalt_Brick",
      "rotation": 2
    },
    {
      "x": -7,
      "y": 74,
      "z": -2,
      "name": "Rock_Basalt_Brick",
      "rotation": 2
    },
    {
      "x": -7,
      "y": 75,
      "z": -2,
      "name": "Rock_Basalt_Brick_Decorative",
      "rotation": 2
    },
    {
      "x": -7,
      "y": 76,
      "z": -2,
      "name": "Rock_Basalt_Brick",
      "rotation": 2
    },
    {
      "x": -7,
      "y": 77,
      "z": -2,
      "name": "Rock_Basalt_Brick_Decorative",
      "rotation": 2
    },
    {
      "x": -7,
      "y": 78,
      "z": -2,
      "name": "Rock_Basalt_Brick",
      "rotation": 2
    },
    {
      "x": -7,
      "y": 79,
      "z": -2,
      "name": "Rock_Basalt_Brick_Decorative",
      "rotation": 2
    },
    {
      "x": -7,
      "y": 80,
      "z": -2,
      "name": "Rock_Basalt_Brick",
      "rotation": 2
    },
    {
      "x": -7,
      "y": 81,
      "z": -2,
      "name": "Rock_Basalt_Brick_Decorative",
      "rotation": 2
    },
    {
      "x": -7,
      "y": 82,
      "z": -2,
      "name": "Rock_Basalt_Brick",
      "rotation": 2
    },
    {
      "x": -7,
      "y": 83,
      "z": -2,
      "name": "Rock_Basalt_Brick_Decorative",
      "rotation": 2
    },
    {
      "x": -7,
      "y": 84,
      "z": -2,
      "name": "Rock_Basalt_Brick",
      "rotation": 2
    },
    {
      "x": -7,
      "y": 85,
      "z": -2,
      "name": "Rock_Basalt_Brick",
      "rotation": 2
    },
    {
      "x": -7,
      "y": 86,
      "z": -2,
      "name": "Rock_Basalt_Brick",
      "rotation": 2
    },
    {
      "x": -7,
      "y": 87,
      "z": -2,
      "name": "Plant_Crop_Mushroom_Block_Brown",
      "rotation": 2
    },
    {
      "x": -7,
      "y": 0,
      "z": -1,
      "name": "Rock_Basalt_Brick",
      "rotation": 2
    },
    {
      "x": -7,
      "y": 1,
      "z": -1,
      "name": "Rock_Basalt_Brick",
      "rotation": 2
    },
    {
      "x": -7,
      "y": 2,
      "z": -1,
      "name": "Rock_Basalt_Brick",
      "rotation": 2
    },
    {
      "x": -7,
      "y": 3,
      "z": -1,
      "name": "Rock_Basalt_Brick",
      "rotation": 2
    },
    {
      "x": -7,
      "y": 4,
      "z": -1,
      "name": "Rock_Basalt_Brick",
      "rotation": 2
    },
    {
      "x": -7,
      "y": 5,
      "z": -1,
      "name": "Rock_Basalt_Brick",
      "rotation": 2
    },
    {
      "x": -7,
      "y": 6,
      "z": -1,
      "name": "Rock_Basalt_Brick",
      "rotation": 2
    },
    {
      "x": -7,
      "y": 7,
      "z": -1,
      "name": "Rock_Basalt_Brick",
      "rotation": 2
    },
    {
      "x": -7,
      "y": 8,
      "z": -1,
      "name": "Rock_Basalt_Brick",
      "rotation": 2
    },
    {
      "x": -7,
      "y": 9,
      "z": -1,
      "name": "Rock_Basalt_Brick",
      "rotation": 2
    },
    {
      "x": -7,
      "y": 10,
      "z": -1,
      "name": "Rock_Basalt_Brick",
      "rotation": 2
    },
    {
      "x": -7,
      "y": 11,
      "z": -1,
      "name": "Rock_Basalt_Brick",
      "rotation": 2
    },
    {
      "x": -7,
      "y": 12,
      "z": -1,
      "name": "Rock_Basalt_Brick",
      "rotation": 2
    },
    {
      "x": -7,
      "y": 13,
      "z": -1,
      "name": "Rock_Basalt_Brick",
      "rotation": 2
    },
    {
      "x": -7,
      "y": 14,
      "z": -1,
      "name": "Rock_Basalt_Brick",
      "rotation": 2
    },
    {
      "x": -7,
      "y": 15,
      "z": -1,
      "name": "Rock_Basalt_Brick",
      "rotation": 2
    },
    {
      "x": -7,
      "y": 16,
      "z": -1,
      "name": "Rock_Basalt_Brick",
      "rotation": 2
    },
    {
      "x": -7,
      "y": 17,
      "z": -1,
      "name": "Rock_Basalt_Brick",
      "rotation": 2
    },
    {
      "x": -7,
      "y": 18,
      "z": -1,
      "name": "Rock_Basalt_Brick",
      "rotation": 2
    },
    {
      "x": -7,
      "y": 19,
      "z": -1,
      "name": "Rock_Basalt_Brick",
      "rotation": 2
    },
    {
      "x": -7,
      "y": 20,
      "z": -1,
      "name": "Rock_Basalt_Brick",
      "rotation": 2
    },
    {
      "x": -7,
      "y": 21,
      "z": -1,
      "name": "Rock_Basalt_Brick",
      "rotation": 2
    },
    {
      "x": -7,
      "y": 22,
      "z": -1,
      "name": "Rock_Basalt_Brick",
      "rotation": 2
    },
    {
      "x": -7,
      "y": 23,
      "z": -1,
      "name": "Rock_Basalt_Brick",
      "rotation": 2
    },
    {
      "x": -7,
      "y": 24,
      "z": -1,
      "name": "Rock_Basalt_Brick",
      "rotation": 2
    },
    {
      "x": -7,
      "y": 25,
      "z": -1,
      "name": "Rock_Basalt_Brick",
      "rotation": 2
    },
    {
      "x": -7,
      "y": 26,
      "z": -1,
      "name": "Rock_Basalt_Brick",
      "rotation": 2
    },
    {
      "x": -7,
      "y": 27,
      "z": -1,
      "name": "Rock_Basalt_Brick",
      "rotation": 2
    },
    {
      "x": -7,
      "y": 28,
      "z": -1,
      "name": "Rock_Basalt_Brick",
      "rotation": 2
    },
    {
      "x": -7,
      "y": 29,
      "z": -1,
      "name": "Rock_Basalt_Brick",
      "rotation": 2
    },
    {
      "x": -7,
      "y": 30,
      "z": -1,
      "name": "Rock_Basalt_Brick",
      "rotation": 2
    },
    {
      "x": -7,
      "y": 31,
      "z": -1,
      "name": "Rock_Basalt_Brick",
      "rotation": 2
    },
    {
      "x": -7,
      "y": 32,
      "z": -1,
      "name": "Rock_Basalt_Brick",
      "rotation": 2
    },
    {
      "x": -7,
      "y": 33,
      "z": -1,
      "name": "Rock_Basalt_Brick",
      "rotation": 2
    },
    {
      "x": -7,
      "y": 34,
      "z": -1,
      "name": "Rock_Basalt_Brick",
      "rotation": 2
    },
    {
      "x": -7,
      "y": 35,
      "z": -1,
      "name": "Rock_Basalt_Brick",
      "rotation": 2
    },
    {
      "x": -7,
      "y": 36,
      "z": -1,
      "name": "Rock_Basalt_Brick",
      "rotation": 2
    },
    {
      "x": -7,
      "y": 37,
      "z": -1,
      "name": "Rock_Basalt_Brick",
      "rotation": 2
    },
    {
      "x": -7,
      "y": 38,
      "z": -1,
      "name": "Rock_Basalt_Brick",
      "rotation": 2
    },
    {
      "x": -7,
      "y": 39,
      "z": -1,
      "name": "Rock_Basalt_Brick",
      "rotation": 2
    },
    {
      "x": -7,
      "y": 40,
      "z": -1,
      "name": "Rock_Basalt_Brick",
      "rotation": 2
    },
    {
      "x": -7,
      "y": 41,
      "z": -1,
      "name": "Rock_Basalt_Brick",
      "rotation": 2
    },
    {
      "x": -7,
      "y": 42,
      "z": -1,
      "name": "Rock_Basalt_Brick",
      "rotation": 2
    },
    {
      "x": -7,
      "y": 43,
      "z": -1,
      "name": "Rock_Basalt_Brick",
      "rotation": 2
    },
    {
      "x": -7,
      "y": 44,
      "z": -1,
      "name": "Rock_Basalt_Brick",
      "rotation": 2
    },
    {
      "x": -7,
      "y": 45,
      "z": -1,
      "name": "Rock_Basalt_Brick",
      "rotation": 2
    },
    {
      "x": -7,
      "y": 46,
      "z": -1,
      "name": "Rock_Basalt_Brick",
      "rotation": 2
    },
    {
      "x": -7,
      "y": 47,
      "z": -1,
      "name": "Rock_Basalt_Brick",
      "rotation": 2
    },
    {
      "x": -7,
      "y": 48,
      "z": -1,
      "name": "Rock_Basalt_Brick",
      "rotation": 2
    },
    {
      "x": -7,
      "y": 49,
      "z": -1,
      "name": "Rock_Basalt_Brick",
      "rotation": 2
    },
    {
      "x": -7,
      "y": 50,
      "z": -1,
      "name": "Rock_Basalt_Brick",
      "rotation": 2
    },
    {
      "x": -7,
      "y": 51,
      "z": -1,
      "name": "Rock_Basalt_Brick",
      "rotation": 2
    },
    {
      "x": -7,
      "y": 52,
      "z": -1,
      "name": "Rock_Basalt_Brick",
      "rotation": 2
    },
    {
      "x": -7,
      "y": 53,
      "z": -1,
      "name": "Rock_Basalt_Brick",
      "rotation": 2
    },
    {
      "x": -7,
      "y": 54,
      "z": -1,
      "name": "Rock_Basalt_Brick",
      "rotation": 2
    },
    {
      "x": -7,
      "y": 55,
      "z": -1,
      "name": "Rock_Basalt_Brick",
      "rotation": 2
    },
    {
      "x": -7,
      "y": 56,
      "z": -1,
      "name": "Rock_Basalt_Brick",
      "rotation": 2
    },
    {
      "x": -7,
      "y": 57,
      "z": -1,
      "name": "Rock_Basalt_Brick",
      "rotation": 2
    },
    {
      "x": -7,
      "y": 58,
      "z": -1,
      "name": "Rock_Basalt_Brick",
      "rotation": 2
    },
    {
      "x": -7,
      "y": 59,
      "z": -1,
      "name": "Rock_Basalt_Brick",
      "rotation": 2
    },
    {
      "x": -7,
      "y": 60,
      "z": -1,
      "name": "Rock_Basalt_Brick",
      "rotation": 2
    },
    {
      "x": -7,
      "y": 61,
      "z": -1,
      "name": "Rock_Basalt_Brick",
      "rotation": 2
    },
    {
      "x": -7,
      "y": 62,
      "z": -1,
      "name": "Rock_Basalt_Brick",
      "rotation": 2
    },
    {
      "x": -7,
      "y": 63,
      "z": -1,
      "name": "Rock_Basalt_Brick",
      "rotation": 2
    },
    {
      "x": -7,
      "y": 64,
      "z": -1,
      "name": "Rock_Basalt_Brick",
      "rotation": 2
    },
    {
      "x": -7,
      "y": 65,
      "z": -1,
      "name": "Rock_Basalt_Brick",
      "rotation": 2
    },
    {
      "x": -7,
      "y": 66,
      "z": -1,
      "name": "Rock_Basalt_Brick",
      "rotation": 2
    },
    {
      "x": -7,
      "y": 67,
      "z": -1,
      "name": "Rock_Basalt_Brick",
      "rotation": 2
    },
    {
      "x": -7,
      "y": 68,
      "z": -1,
      "name": "Rock_Basalt_Brick",
      "rotation": 2
    },
    {
      "x": -7,
      "y": 69,
      "z": -1,
      "name": "Rock_Basalt_Brick",
      "rotation": 2
    },
    {
      "x": -7,
      "y": 70,
      "z": -1,
      "name": "Rock_Basalt_Brick",
      "rotation": 2
    },
    {
      "x": -7,
      "y": 71,
      "z": -1,
      "name": "Rock_Basalt_Brick",
      "rotation": 2
    },
    {
      "x": -7,
      "y": 72,
      "z": -1,
      "name": "Rock_Basalt_Brick",
      "rotation": 2
    },
    {
      "x": -7,
      "y": 73,
      "z": -1,
      "name": "Rock_Basalt_Brick",
      "rotation": 2
    },
    {
      "x": -7,
      "y": 74,
      "z": -1,
      "name": "Rock_Basalt_Brick",
      "rotation": 2
    },
    {
      "x": -7,
      "y": 75,
      "z": -1,
      "name": "Rock_Basalt_Brick_Decorative",
      "rotation": 2
    },
    {
      "x": -7,
      "y": 76,
      "z": -1,
      "name": "Rock_Basalt_Brick",
      "rotation": 2
    },
    {
      "x": -7,
      "y": 77,
      "z": -1,
      "name": "Rock_Basalt_Brick_Decorative",
      "rotation": 2
    },
    {
      "x": -7,
      "y": 78,
      "z": -1,
      "name": "Rock_Basalt_Brick",
      "rotation": 2
    },
    {
      "x": -7,
      "y": 79,
      "z": -1,
      "name": "Rock_Basalt_Brick_Decorative",
      "rotation": 2
    },
    {
      "x": -7,
      "y": 80,
      "z": -1,
      "name": "Rock_Basalt_Brick",
      "rotation": 2
    },
    {
      "x": -7,
      "y": 81,
      "z": -1,
      "name": "Rock_Basalt_Brick_Decorative",
      "rotation": 2
    },
    {
      "x": -7,
      "y": 82,
      "z": -1,
      "name": "Rock_Basalt_Brick",
      "rotation": 2
    },
    {
      "x": -7,
      "y": 83,
      "z": -1,
      "name": "Rock_Basalt_Brick_Decorative",
      "rotation": 2
    },
    {
      "x": -7,
      "y": 84,
      "z": -1,
      "name": "Rock_Basalt_Brick",
      "rotation": 2
    },
    {
      "x": -7,
      "y": 85,
      "z": -1,
      "name": "Rock_Basalt_Brick",
      "rotation": 2
    },
    {
      "x": -7,
      "y": 86,
      "z": -1,
      "name": "Rock_Basalt_Brick",
      "rotation": 2
    },
    {
      "x": -7,
      "y": 0,
      "z": 0,
      "name": "Rock_Basalt_Brick",
      "rotation": 2
    },
    {
      "x": -7,
      "y": 1,
      "z": 0,
      "name": "Rock_Basalt_Brick",
      "rotation": 2
    },
    {
      "x": -7,
      "y": 2,
      "z": 0,
      "name": "Rock_Basalt_Brick",
      "rotation": 2
    },
    {
      "x": -7,
      "y": 3,
      "z": 0,
      "name": "Rock_Basalt_Brick",
      "rotation": 2
    },
    {
      "x": -7,
      "y": 4,
      "z": 0,
      "name": "Rock_Basalt_Brick",
      "rotation": 2
    },
    {
      "x": -7,
      "y": 5,
      "z": 0,
      "name": "Rock_Basalt_Brick",
      "rotation": 2
    },
    {
      "x": -7,
      "y": 6,
      "z": 0,
      "name": "Rock_Basalt_Brick",
      "rotation": 2
    },
    {
      "x": -7,
      "y": 7,
      "z": 0,
      "name": "Rock_Basalt_Brick",
      "rotation": 2
    },
    {
      "x": -7,
      "y": 8,
      "z": 0,
      "name": "Rock_Basalt_Brick",
      "rotation": 2
    },
    {
      "x": -7,
      "y": 9,
      "z": 0,
      "name": "Rock_Basalt_Brick",
      "rotation": 2
    },
    {
      "x": -7,
      "y": 10,
      "z": 0,
      "name": "Rock_Basalt_Brick",
      "rotation": 2
    },
    {
      "x": -7,
      "y": 11,
      "z": 0,
      "name": "Rock_Basalt_Brick",
      "rotation": 2
    },
    {
      "x": -7,
      "y": 12,
      "z": 0,
      "name": "Rock_Basalt_Brick",
      "rotation": 2
    },
    {
      "x": -7,
      "y": 13,
      "z": 0,
      "name": "Rock_Basalt_Brick",
      "rotation": 2
    },
    {
      "x": -7,
      "y": 14,
      "z": 0,
      "name": "Rock_Basalt_Brick",
      "rotation": 2
    },
    {
      "x": -7,
      "y": 15,
      "z": 0,
      "name": "Rock_Basalt_Brick",
      "rotation": 2
    },
    {
      "x": -7,
      "y": 16,
      "z": 0,
      "name": "Rock_Basalt_Brick",
      "rotation": 2
    },
    {
      "x": -7,
      "y": 17,
      "z": 0,
      "name": "Rock_Basalt_Brick",
      "rotation": 2
    },
    {
      "x": -7,
      "y": 18,
      "z": 0,
      "name": "Rock_Basalt_Brick",
      "rotation": 2
    },
    {
      "x": -7,
      "y": 19,
      "z": 0,
      "name": "Rock_Basalt_Brick",
      "rotation": 2
    },
    {
      "x": -7,
      "y": 20,
      "z": 0,
      "name": "Rock_Basalt_Brick",
      "rotation": 2
    },
    {
      "x": -7,
      "y": 21,
      "z": 0,
      "name": "Rock_Basalt_Brick",
      "rotation": 2
    },
    {
      "x": -7,
      "y": 22,
      "z": 0,
      "name": "Rock_Basalt_Brick",
      "rotation": 2
    },
    {
      "x": -7,
      "y": 23,
      "z": 0,
      "name": "Rock_Basalt_Brick",
      "rotation": 2
    },
    {
      "x": -7,
      "y": 24,
      "z": 0,
      "name": "Rock_Basalt_Brick",
      "rotation": 2
    },
    {
      "x": -7,
      "y": 25,
      "z": 0,
      "name": "Rock_Basalt_Brick",
      "rotation": 2
    },
    {
      "x": -7,
      "y": 26,
      "z": 0,
      "name": "Rock_Basalt_Brick",
      "rotation": 2
    },
    {
      "x": -7,
      "y": 27,
      "z": 0,
      "name": "Rock_Basalt_Brick",
      "rotation": 2
    },
    {
      "x": -7,
      "y": 28,
      "z": 0,
      "name": "Rock_Basalt_Brick",
      "rotation": 2
    },
    {
      "x": -7,
      "y": 29,
      "z": 0,
      "name": "Rock_Basalt_Brick",
      "rotation": 2
    },
    {
      "x": -7,
      "y": 30,
      "z": 0,
      "name": "Rock_Basalt_Brick",
      "rotation": 2
    },
    {
      "x": -7,
      "y": 31,
      "z": 0,
      "name": "Rock_Basalt_Brick",
      "rotation": 2
    },
    {
      "x": -7,
      "y": 32,
      "z": 0,
      "name": "Rock_Basalt_Brick",
      "rotation": 2
    },
    {
      "x": -7,
      "y": 33,
      "z": 0,
      "name": "Rock_Basalt_Brick",
      "rotation": 2
    },
    {
      "x": -7,
      "y": 34,
      "z": 0,
      "name": "Rock_Basalt_Brick",
      "rotation": 2
    },
    {
      "x": -7,
      "y": 35,
      "z": 0,
      "name": "Rock_Basalt_Brick",
      "rotation": 2
    },
    {
      "x": -7,
      "y": 36,
      "z": 0,
      "name": "Rock_Basalt_Brick",
      "rotation": 2
    },
    {
      "x": -7,
      "y": 37,
      "z": 0,
      "name": "Rock_Basalt_Brick",
      "rotation": 2
    },
    {
      "x": -7,
      "y": 38,
      "z": 0,
      "name": "Rock_Basalt_Brick",
      "rotation": 2
    },
    {
      "x": -7,
      "y": 39,
      "z": 0,
      "name": "Rock_Basalt_Brick",
      "rotation": 2
    },
    {
      "x": -7,
      "y": 40,
      "z": 0,
      "name": "Rock_Basalt_Brick",
      "rotation": 2
    },
    {
      "x": -7,
      "y": 41,
      "z": 0,
      "name": "Rock_Basalt_Brick",
      "rotation": 2
    },
    {
      "x": -7,
      "y": 42,
      "z": 0,
      "name": "Rock_Basalt_Brick",
      "rotation": 2
    },
    {
      "x": -7,
      "y": 43,
      "z": 0,
      "name": "Rock_Basalt_Brick",
      "rotation": 2
    },
    {
      "x": -7,
      "y": 44,
      "z": 0,
      "name": "Rock_Basalt_Brick",
      "rotation": 2
    },
    {
      "x": -7,
      "y": 45,
      "z": 0,
      "name": "Rock_Basalt_Brick",
      "rotation": 2
    },
    {
      "x": -7,
      "y": 46,
      "z": 0,
      "name": "Rock_Basalt_Brick",
      "rotation": 2
    },
    {
      "x": -7,
      "y": 47,
      "z": 0,
      "name": "Rock_Basalt_Brick",
      "rotation": 2
    },
    {
      "x": -7,
      "y": 48,
      "z": 0,
      "name": "Rock_Basalt_Brick",
      "rotation": 2
    },
    {
      "x": -7,
      "y": 49,
      "z": 0,
      "name": "Rock_Basalt_Brick",
      "rotation": 2
    },
    {
      "x": -7,
      "y": 50,
      "z": 0,
      "name": "Rock_Basalt_Brick",
      "rotation": 2
    },
    {
      "x": -7,
      "y": 51,
      "z": 0,
      "name": "Rock_Basalt_Brick",
      "rotation": 2
    },
    {
      "x": -7,
      "y": 52,
      "z": 0,
      "name": "Rock_Basalt_Brick",
      "rotation": 2
    },
    {
      "x": -7,
      "y": 53,
      "z": 0,
      "name": "Rock_Basalt_Brick",
      "rotation": 2
    },
    {
      "x": -7,
      "y": 54,
      "z": 0,
      "name": "Rock_Basalt_Brick",
      "rotation": 2
    },
    {
      "x": -7,
      "y": 55,
      "z": 0,
      "name": "Rock_Basalt_Brick",
      "rotation": 2
    },
    {
      "x": -7,
      "y": 56,
      "z": 0,
      "name": "Rock_Basalt_Brick",
      "rotation": 2
    },
    {
      "x": -7,
      "y": 57,
      "z": 0,
      "name": "Rock_Basalt_Brick",
      "rotation": 2
    },
    {
      "x": -7,
      "y": 58,
      "z": 0,
      "name": "Rock_Basalt_Brick",
      "rotation": 2
    },
    {
      "x": -7,
      "y": 59,
      "z": 0,
      "name": "Rock_Basalt_Brick",
      "rotation": 2
    },
    {
      "x": -7,
      "y": 60,
      "z": 0,
      "name": "Rock_Basalt_Brick",
      "rotation": 2
    },
    {
      "x": -7,
      "y": 61,
      "z": 0,
      "name": "Rock_Basalt_Brick",
      "rotation": 2
    },
    {
      "x": -7,
      "y": 62,
      "z": 0,
      "name": "Rock_Basalt_Brick",
      "rotation": 2
    },
    {
      "x": -7,
      "y": 63,
      "z": 0,
      "name": "Rock_Basalt_Brick",
      "rotation": 2
    },
    {
      "x": -7,
      "y": 64,
      "z": 0,
      "name": "Rock_Basalt_Brick",
      "rotation": 2
    },
    {
      "x": -7,
      "y": 65,
      "z": 0,
      "name": "Rock_Basalt_Brick",
      "rotation": 2
    },
    {
      "x": -7,
      "y": 66,
      "z": 0,
      "name": "Rock_Basalt_Brick",
      "rotation": 2
    },
    {
      "x": -7,
      "y": 67,
      "z": 0,
      "name": "Rock_Basalt_Brick",
      "rotation": 2
    },
    {
      "x": -7,
      "y": 68,
      "z": 0,
      "name": "Rock_Basalt_Brick",
      "rotation": 2
    },
    {
      "x": -7,
      "y": 69,
      "z": 0,
      "name": "Rock_Basalt_Brick",
      "rotation": 2
    },
    {
      "x": -7,
      "y": 70,
      "z": 0,
      "name": "Rock_Basalt_Brick",
      "rotation": 2
    },
    {
      "x": -7,
      "y": 71,
      "z": 0,
      "name": "Rock_Basalt_Brick",
      "rotation": 2
    },
    {
      "x": -7,
      "y": 72,
      "z": 0,
      "name": "Rock_Basalt_Brick_Decorative",
      "rotation": 2
    },
    {
      "x": -7,
      "y": 73,
      "z": 0,
      "name": "Rock_Basalt_Brick_Decorative",
      "rotation": 2
    },
    {
      "x": -7,
      "y": 74,
      "z": 0,
      "name": "Rock_Basalt_Brick_Decorative",
