{
  "version": 8,
  "blockIdVersion": 11,
  "anchorX": 0,
  "anchorY": 0,
  "anchorZ": 0,
  "blocks": [
    {
      "x": -7,
      "y": 6,
      "z": 0,
      "name": "Deco_Bone_Full",
      "rotation": 5
    },
    {
      "x": -7,
      "y": 7,
      "z": 0,
      "name": "Deco_Bone_Full"
    },
    {
      "x": -7,
      "y": 8,
      "z": 0,
      "name": "Deco_Bone_Full"
    },
    {
      "x": -7,
      "y": 9,
      "z": 0,
      "name": "Deco_Bone_Full"
    },
    {
      "x": -7,
      "y": 10,
      "z": 0,
      "name": "Deco_Bone_Ribs_Long"
    },
    {
      "x": -6,
      "y": 5,
      "z": -2,
      "name": "Deco_Bone_Full",
      "rotation": 5
    },
    {
      "x": -6,
      "y": 6,
      "z": -2,
      "name": "Deco_Bone_Full"
    },
    {
      "x": -6,
      "y": 7,
      "z": -2,
      "name": "Deco_Bone_Full"
    },
    {
      "x": -6,
      "y": 8,
      "z": -2,
      "name": "Deco_Bone_Full"
    },
    {
      "x": -6,
      "y": 9,
      "z": -2,
      "name": "Deco_Bone_Ribs_Long"
    },
    {
      "x": -6,
      "y": 3,
      "z": 0,
      "name": "Deco_Bone_Full",
      "rotation": 5
    },
    {
      "x": -6,
      "y": 4,
      "z": 0,
      "name": "Deco_Bone_Full"
    },
    {
      "x": -6,
      "y": 5,
      "z": 0,
      "name": "Deco_Bone_Full"
    },
    {
      "x": -6,
      "y": 6,
      "z": 0,
      "name": "Deco_Bone_Full"
    },
    {
      "x": -6,
      "y": 7,
      "z": 0,
      "name": "Deco_Bone_Ribs_Long"
    },
    {
      "x": -6,
      "y": 5,
      "z": 2,
      "name": "Deco_Bone_Full",
      "rotation": 5
    },
    {
      "x": -6,
      "y": 6,
      "z": 2,
      "name": "Deco_Bone_Full"
    },
    {
      "x": -6,
      "y": 7,
      "z": 2,
      "name": "Deco_Bone_Full"
    },
    {
      "x": -6,
      "y": 8,
      "z": 2,
      "name": "Deco_Bone_Full"
    },
    {
      "x": -6,
      "y": 9,
      "z": 2,
      "name": "Deco_Bone_Ribs_Long"
    },
    {
      "x": -6,
      "y": 5,
      "z": 4,
      "name": "Deco_Bone_Full",
      "rotation": 5
    },
    {
      "x": -6,
      "y": 6,
      "z": 4,
      "name": "Deco_Bone_Full"
    },
    {
      "x": -6,
      "y": 7,
      "z": 4,
      "name": "Deco_Bone_Full"
    },
    {
      "x": -6,
      "y": 8,
      "z": 4,
      "name": "Deco_Bone_Full"
    },
    {
      "x": -6,
      "y": 9,
      "z": 4,
      "name": "Deco_Bone_Ribs_Long"
    },
    {
      "x": -5,
      "y": 5,
      "z": -4,
      "name": "Deco_Bone_Full",
      "rotation": 5
    },
    {
      "x": -5,
      "y": 6,
      "z": -4,
      "name": "Deco_Bone_Full"
    },
    {
      "x": -5,
      "y": 7,
      "z": -4,
      "name": "Deco_Bone_Full"
    },
    {
      "x": -5,
      "y": 8,
      "z": -4,
      "name": "Deco_Bone_Full"
    },
    {
      "x": -5,
      "y": 9,
      "z": -4,
      "name": "Deco_Bone_Ribs_Long"
    },
    {
      "x": -5,
      "y": 2,
      "z": -2,
      "name": "Deco_Bone_Full",
      "rotation": 5
    },
    {
      "x": -5,
      "y": 3,
      "z": -2,
      "name": "Deco_Bone_Full"
    },
    {
      "x": -5,
      "y": 4,
      "z": -2,
      "name": "Deco_Bone_Full"
    },
    {
      "x": -5,
      "y": 5,
      "z": -2,
      "name": "Deco_Bone_Full"
    },
    {
      "x": -5,
      "y": 6,
      "z": -2,
      "name": "Deco_Bone_Ribs_Long"
    },
    {
      "x": -5,
      "y": 0,
      "z": 0,
      "name": "Deco_Bone_Full",
      "rotation": 5
    },
    {
      "x": -5,
      "y": 1,
      "z": 0,
      "name": "Deco_Bone_Full"
    },
    {
      "x": -5,
      "y": 2,
      "z": 0,
      "name": "Deco_Bone_Full"
    },
    {
      "x": -5,
      "y": 3,
      "z": 0,
      "name": "Deco_Bone_Full"
    },
    {
      "x": -5,
      "y": 4,
      "z": 0,
      "name": "Deco_Bone_Ribs_Long"
    },
    {
      "x": -5,
      "y": 2,
      "z": 2,
      "name": "Deco_Bone_Full",
      "rotation": 5
    },
    {
      "x": -5,
      "y": 3,
      "z": 2,
      "name": "Deco_Bone_Full"
    },
    {
      "x": -5,
      "y": 4,
      "z": 2,
      "name": "Deco_Bone_Full"
    },
    {
      "x": -5,
      "y": 5,
      "z": 2,
      "name": "Deco_Bone_Full"
    },
    {
      "x": -5,
      "y": 6,
      "z": 2,
      "name": "Deco_Bone_Ribs_Long"
    },
    {
      "x": -5,
      "y": 2,
      "z": 4,
      "name": "Deco_Bone_Full",
      "rotation": 5
    },
    {
      "x": -5,
      "y": 3,
      "z": 4,
      "name": "Deco_Bone_Full"
    },
    {
      "x": -5,
      "y": 4,
      "z": 4,
      "name": "Deco_Bone_Full"
    },
    {
      "x": -5,
      "y": 5,
      "z": 4,
      "name": "Deco_Bone_Full"
    },
    {
      "x": -5,
      "y": 6,
      "z": 4,
      "name": "Deco_Bone_Ribs_Long"
    },
    {
      "x": -5,
      "y": 5,
      "z": 6,
      "name": "Deco_Bone_Full",
      "rotation": 5
    },
    {
      "x": -5,
      "y": 6,
      "z": 6,
      "name": "Deco_Bone_Full"
    },
    {
      "x": -5,
      "y": 7,
      "z": 6,
      "name": "Deco_Bone_Full"
    },
    {
      "x": -5,
      "y": 8,
      "z": 6,
      "name": "Deco_Bone_Ribs_Long"
    },
    {
      "x": -4,
      "y": 4,
      "z": -6,
      "name": "Deco_Bone_Full",
      "rotation": 5
    },
    {
      "x": -4,
      "y": 5,
      "z": -6,
      "name": "Deco_Bone_Full"
    },
    {
      "x": -4,
      "y": 6,
      "z": -6,
      "name": "Deco_Bone_Full"
    },
    {
      "x": -4,
      "y": 7,
      "z": -6,
      "name": "Deco_Bone_Ribs_Long"
    },
    {
      "x": -4,
      "y": 2,
      "z": -4,
      "name": "Deco_Bone_Full",
      "rotation": 5
    },
    {
      "x": -4,
      "y": 3,
      "z": -4,
      "name": "Deco_Bone_Full"
    },
    {
      "x": -4,
      "y": 4,
      "z": -4,
      "name": "Deco_Bone_Full"
    },
    {
      "x": -4,
      "y": 5,
      "z": -4,
      "name": "Deco_Bone_Full"
    },
    {
      "x": -4,
      "y": 6,
      "z": -4,
      "name": "Deco_Bone_Ribs_Long"
    },
    {
      "x": -4,
      "y": 0,
      "z": -2,
      "name": "Deco_Bone_Full",
      "rotation": 5
    },
    {
      "x": -4,
      "y": 1,
      "z": -2,
      "name": "Deco_Bone_Full"
    },
    {
      "x": -4,
      "y": 2,
      "z": -2,
      "name": "Deco_Bone_Full"
    },
    {
      "x": -4,
      "y": 3,
      "z": -2,
      "name": "Deco_Bone_Ribs_Long"
    },
    {
      "x": -4,
      "y": 0,
      "z": 0,
      "name": "Deco_Bone_Full",
      "rotation": 5
    },
    {
      "x": -4,
      "y": 0,
      "z": 2,
      "name": "Deco_Bone_Full",
      "rotation": 5
    },
    {
      "x": -4,
      "y": 1,
      "z": 2,
      "name": "Deco_Bone_Full"
    },
    {
      "x": -4,
      "y": 2,
      "z": 2,
      "name": "Deco_Bone_Full"
    },
    {
      "x": -4,
      "y": 3,
      "z": 2,
      "name": "Deco_Bone_Ribs_Long"
    },
    {
      "x": -4,
      "y": 0,
      "z": 4,
      "name": "Deco_Bone_Full",
      "rotation": 5
    },
    {
      "x": -4,
      "y": 1,
      "z": 4,
      "name": "Deco_Bone_Full"
    },
    {
      "x": -4,
      "y": 2,
      "z": 4,
      "name": "Deco_Bone_Full"
    },
    {
      "x": -4,
      "y": 3,
      "z": 4,
      "name": "Deco_Bone_Ribs_Long"
    },
    {
      "x": -4,
      "y": 2,
      "z": 6,
      "name": "Deco_Bone_Full",
      "rotation": 5
    },
    {
      "x": -4,
      "y": 3,
      "z": 6,
      "name": "Deco_Bone_Full"
    },
    {
      "x": -4,
      "y": 4,
      "z": 6,
      "name": "Deco_Bone_Full"
    },
    {
      "x": -4,
      "y": 5,
      "z": 6,
      "name": "Deco_Bone_Full"
    },
    {
      "x": -4,
      "y": 6,
      "z": 6,
      "name": "Deco_Bone_Ribs_Long"
    },
    {
      "x": -4,
      "y": 4,
      "z": 8,
      "name": "Deco_Bone_Full",
      "rotation": 5
    },
    {
      "x": -4,
      "y": 5,
      "z": 8,
      "name": "Deco_Bone_Full"
    },
    {
      "x": -4,
      "y": 6,
      "z": 8,
      "name": "Deco_Bone_Full"
    },
    {
      "x": -4,
      "y": 7,
      "z": 8,
      "name": "Deco_Bone_Ribs_Long"
    },
    {
      "x": -3,
      "y": 2,
      "z": -6,
      "name": "Deco_Bone_Full",
      "rotation": 5
    },
    {
      "x": -3,
      "y": 3,
      "z": -6,
      "name": "Deco_Bone_Full"
    },
    {
      "x": -3,
      "y": 4,
      "z": -6,
      "name": "Deco_Bone_Full"
    },
    {
      "x": -3,
      "y": 5,
      "z": -6,
      "name": "Deco_Bone_Ribs_Long"
    },
    {
      "x": -3,
      "y": 0,
      "z": -4,
      "name": "Deco_Bone_Full",
      "rotation": 5
    },
    {
      "x": -3,
      "y": 1,
      "z": -4,
      "name": "Deco_Bone_Full"
    },
    {
      "x": -3,
      "y": 2,
      "z": -4,
      "name": "Deco_Bone_Full"
    },
    {
      "x": -3,
      "y": 3,
      "z": -4,
      "name": "Deco_Bone_Ribs_Long"
    },
    {
      "x": -3,
      "y": 0,
      "z": -2,
      "name": "Deco_Bone_Full",
      "rotation": 5
    },
    {
      "x": -3,
      "y": 0,
      "z": 0,
      "name": "Deco_Bone_Full",
      "rotation": 5
    },
    {
      "x": -3,
      "y": 0,
      "z": 2,
      "name": "Deco_Bone_Full",
      "rotation": 5
    },
    {
      "x": -3,
      "y": 0,
      "z": 4,
      "name": "Deco_Bone_Full",
      "rotation": 5
    },
    {
      "x": -3,
      "y": 0,
      "z": 6,
      "name": "Deco_Bone_Full",
      "rotation": 5
    },
    {
      "x": -3,
      "y": 1,
      "z": 6,
      "name": "Deco_Bone_Full"
    },
    {
      "x": -3,
      "y": 2,
      "z": 6,
      "name": "Deco_Bone_Full"
    },
    {
      "x": -3,
      "y": 3,
      "z": 6,
      "name": "Deco_Bone_Ribs_Long"
    },
    {
      "x": -3,
      "y": 2,
      "z": 8,
      "name": "Deco_Bone_Full",
      "rotation": 5
    },
    {
      "x": -3,
      "y": 3,
      "z": 8,
      "name": "Deco_Bone_Full"
    },
    {
      "x": -3,
      "y": 4,
      "z": 8,
      "name": "Deco_Bone_Full"
    },
    {
      "x": -3,
      "y": 5,
      "z": 8,
      "name": "Deco_Bone_Ribs_Long"
    },
    {
      "x": -2,
      "y": 0,
      "z": -6,
      "name": "Deco_Bone_Full",
      "rotation": 5
    },
    {
      "x": -2,
      "y": 1,
      "z": -6,
      "name": "Deco_Bone_Full"
    },
    {
      "x": -2,
      "y": 2,
      "z": -6,
      "name": "Deco_Bone_Full"
    },
    {
      "x": -2,
      "y": 3,
      "z": -6,
      "name": "Deco_Bone_Ribs_Long"
    },
    {
      "x": -2,
      "y": 0,
      "z": -4,
      "name": "Deco_Bone_Full",
      "rotation": 5
    },
    {
      "x": -2,
      "y": 0,
      "z": -2,
      "name": "Deco_Bone_Full",
      "rotation": 5
    },
    {
      "x": -2,
      "y": 0,
      "z": 0,
      "name": "Deco_Bone_Full",
      "rotation": 5
    },
    {
      "x": -2,
      "y": 0,
      "z": 2,
      "name": "Deco_Bone_Full",
      "rotation": 5
    },
    {
      "x": -2,
      "y": 0,
      "z": 4,
      "name": "Deco_Bone_Full",
      "rotation": 5
    },
    {
      "x": -2,
      "y": 0,
      "z": 6,
      "name": "Deco_Bone_Full",
      "rotation": 5
    },
    {
      "x": -2,
      "y": 0,
      "z": 8,
      "name": "Deco_Bone_Full",
      "rotation": 5
    },
    {
      "x": -2,
      "y": 1,
      "z": 8,
      "name": "Deco_Bone_Full"
    },
    {
      "x": -2,
      "y": 2,
      "z": 8,
      "name": "Deco_Bone_Full"
    },
    {
      "x": -2,
      "y": 3,
      "z": 8,
      "name": "Deco_Bone_Ribs_Long"
    },
    {
      "x": -1,
      "y": 0,
      "z": -6,
      "name": "Deco_Bone_Full",
      "rotation": 5
    },
    {
      "x": -1,
      "y": 0,
      "z": -4,
      "name": "Deco_Bone_Full",
      "rotation": 5
    },
    {
      "x": -1,
      "y": 0,
      "z": -2,
      "name": "Deco_Bone_Full",
      "rotation": 5
    },
    {
      "x": -1,
      "y": 0,
      "z": 0,
      "name": "Deco_Bone_Full",
      "rotation": 5
    },
    {
      "x": -1,
      "y": 0,
      "z": 2,
      "name": "Deco_Bone_Full",
      "rotation": 5
    },
    {
      "x": -1,
      "y": 0,
      "z": 4,
      "name": "Deco_Bone_Full",
      "rotation": 5
    },
    {
      "x": -1,
      "y": 0,
      "z": 6,
      "name": "Deco_Bone_Full",
      "rotation": 5
    },
    {
      "x": -1,
      "y": 0,
      "z": 8,
      "name": "Deco_Bone_Full",
      "rotation": 5
    },
    {
      "x": 0,
      "y": 2,
      "z": -11,
      "name": "Deco_Bone_Spine"
    },
    {
      "x": 0,
      "y": 3,
      "z": -11,
      "name": "Deco_Bone_Spine"
    },
    {
      "x": 0,
      "y": 1,
      "z": -10,
      "name": "Deco_Bone_Spine"
    },
    {
      "x": 0,
      "y": 2,
      "z": -10,
      "name": "Deco_Bone_Full",
      "rotation": 4
    },
    {
      "x": 0,
      "y": 3,
      "z": -10,
      "name": "Deco_Bone_Full"
    },
    {
      "x": 0,
      "y": 4,
      "z": -10,
      "name": "Deco_Bone_Spike"
    },
    {
      "x": 0,
      "y": 1,
      "z": -9,
      "name": "Deco_Bone_Full",
      "rotation": 4
    },
    {
      "x": 0,
      "y": 2,
      "z": -9,
      "name": "Deco_Bone_Full"
    },
    {
      "x": 0,
      "y": 3,
      "z": -9,
      "name": "Deco_Bone_Spine"
    },
    {
      "x": 0,
      "y": 0,
      "z": -8,
      "name": "Deco_Bone_Spine"
    },
    {
      "x": 0,
      "y": 1,
      "z": -8,
      "name": "Deco_Bone_Full",
      "rotation": 4
    },
    {
      "x": 0,
      "y": 2,
      "z": -8,
      "name": "Deco_Bone_Spine"
    },
    {
      "x": 0,
      "y": 3,
      "z": -8,
      "name": "Deco_Bone_Spine"
    },
    {
      "x": 0,
      "y": 0,
      "z": -7,
      "name": "Deco_Bone_Full",
      "rotation": 4
    },
    {
      "x": 0,
      "y": 1,
      "z": -7,
      "name": "Deco_Bone_Full"
    },
    {
      "x": 0,
      "y": 2,
      "z": -7,
      "name": "Deco_Bone_Spine"
    },
    {
      "x": 0,
      "y": 0,
      "z": -6,
      "name": "Deco_Bone_Full",
      "rotation": 4
    },
    {
      "x": 0,
      "y": 1,
      "z": -6,
      "name": "Deco_Bone_Spine"
    },
    {
      "x": 0,
      "y": 2,
      "z": -6,
      "name": "Deco_Bone_Spine"
    },
    {
      "x": 0,
      "y": 0,
      "z": -5,
      "name": "Deco_Bone_Full",
      "rotation": 4
    },
    {
      "x": 0,
      "y": 1,
      "z": -5,
      "name": "Deco_Bone_Spine"
    },
    {
      "x": 0,
      "y": 0,
      "z": -4,
      "name": "Deco_Bone_Full",
      "rotation": 4
    },
    {
      "x": 0,
      "y": 1,
      "z": -4,
      "name": "Deco_Bone_Spine"
    },
    {
      "x": 0,
      "y": 0,
      "z": -3,
      "name": "Deco_Bone_Full",
      "rotation": 4
    },
    {
      "x": 0,
      "y": 1,
      "z": -3,
      "name": "Deco_Bone_Spine"
    },
    {
      "x": 0,
      "y": 0,
      "z": -2,
      "name": "Deco_Bone_Full",
      "rotation": 4
    },
    {
      "x": 0,
      "y": 1,
      "z": -2,
      "name": "Deco_Bone_Spine"
    },
    {
      "x": 0,
      "y": 0,
      "z": -1,
      "name": "Deco_Bone_Full",
      "rotation": 4
    },
    {
      "x": 0,
      "y": 1,
      "z": -1,
      "name": "Deco_Bone_Spine"
    },
    {
      "x": 0,
      "y": 0,
      "z": 0,
      "name": "Deco_Bone_Full",
      "rotation": 4
    },
    {
      "x": 0,
      "y": 1,
      "z": 0,
      "name": "Deco_Bone_Spine"
    },
    {
      "x": 0,
      "y": 0,
      "z": 1,
      "name": "Deco_Bone_Full",
      "rotation": 4
    },
    {
      "x": 0,
      "y": 1,
      "z": 1,
      "name": "Deco_Bone_Spine"
    },
    {
      "x": 0,
      "y": 0,
      "z": 2,
      "name": "Deco_Bone_Full",
      "rotation": 4
    },
    {
      "x": 0,
      "y": 1,
      "z": 2,
      "name": "Deco_Bone_Spine"
    },
    {
      "x": 0,
      "y": 0,
      "z": 3,
      "name": "Deco_Bone_Full",
      "rotation": 4
    },
    {
      "x": 0,
      "y": 1,
      "z": 3,
      "name": "Deco_Bone_Spine"
    },
    {
      "x": 0,
      "y": 0,
      "z": 4,
      "name": "Deco_Bone_Full",
      "rotation": 4
    },
    {
      "x": 0,
      "y": 1,
      "z": 4,
      "name": "Deco_Bone_Spine"
    },
    {
      "x": 0,
      "y": 0,
      "z": 5,
      "name": "Deco_Bone_Full",
      "rotation": 4
    },
    {
      "x": 0,
      "y": 1,
      "z": 5,
      "name": "Deco_Bone_Spine"
    },
    {
      "x": 0,
      "y": 0,
      "z": 6,
      "name": "Deco_Bone_Full",
      "rotation": 4
    },
    {
      "x": 0,
      "y": 1,
      "z": 6,
      "name": "Deco_Bone_Spine"
    },
    {
      "x": 0,
      "y": 0,
      "z": 7,
      "name": "Deco_Bone_Full",
      "rotation": 4
    },
    {
      "x": 0,
      "y": 1,
      "z": 7,
      "name": "Deco_Bone_Spine"
    },
    {
      "x": 0,
      "y": 0,
      "z": 8,
      "name": "Deco_Bone_Full",
      "rotation": 4
    },
    {
      "x": 0,
      "y": 1,
      "z": 8,
      "name": "Deco_Bone_Spine"
    },
    {
      "x": 0,
      "y": 2,
      "z": 8,
      "name": "Deco_Bone_Spine",
      "rotation": 1
    },
    {
      "x": 0,
      "y": 0,
      "z": 9,
      "name": "Deco_Bone_Full",
      "rotation": 4
    },
    {
      "x": 0,
      "y": 1,
      "z": 9,
      "name": "Deco_Bone_Full"
    },
    {
      "x": 0,
      "y": 2,
      "z": 9,
      "name": "Deco_Bone_Spine",
      "rotation": 1
    },
    {
      "x": 0,
      "y": 0,
      "z": 10,
      "name": "Deco_Bone_Spine"
    },
    {
      "x": 0,
      "y": 1,
      "z": 10,
      "name": "Deco_Bone_Full",
      "rotation": 4
    },
    {
      "x": 0,
      "y": 2,
      "z": 10,
      "name": "Deco_Bone_Full"
    },
    {
      "x": 0,
      "y": 3,
      "z": 10,
      "name": "Deco_Bone_Spike"
    },
    {
      "x": 0,
      "y": 1,
      "z": 11,
      "name": "Deco_Bone_Spine"
    },
    {
      "x": 0,
      "y": 2,
      "z": 11,
      "name": "Deco_Bone_Spine"
    },
    {
      "x": 1,
      "y": 0,
      "z": -6,
      "name": "Deco_Bone_Full",
      "rotation": 5
    },
    {
      "x": 1,
      "y": 0,
      "z": -4,
      "name": "Deco_Bone_Full",
      "rotation": 5
    },
    {
      "x": 1,
      "y": 0,
      "z": -2,
      "name": "Deco_Bone_Full",
      "rotation": 5
    },
    {
      "x": 1,
      "y": 0,
      "z": 0,
      "name": "Deco_Bone_Full",
      "rotation": 5
    },
    {
      "x": 1,
      "y": 0,
      "z": 2,
      "name": "Deco_Bone_Full",
      "rotation": 5
    },
    {
      "x": 1,
      "y": 0,
      "z": 4,
      "name": "Deco_Bone_Full",
      "rotation": 5
    },
    {
      "x": 1,
      "y": 0,
      "z": 6,
      "name": "Deco_Bone_Full",
      "rotation": 5
    },
    {
      "x": 1,
      "y": 0,
      "z": 8,
      "name": "Deco_Bone_Full",
      "rotation": 5
    },
    {
      "x": 2,
      "y": 0,
      "z": -6,
      "name": "Deco_Bone_Full",
      "rotation": 5
    },
    {
      "x": 2,
      "y": 1,
      "z": -6,
      "name": "Deco_Bone_Full"
    },
    {
      "x": 2,
      "y": 2,
      "z": -6,
      "name": "Deco_Bone_Full"
    },
    {
      "x": 2,
      "y": 3,
      "z": -6,
      "name": "Deco_Bone_Ribs_Long"
    },
    {
      "x": 2,
      "y": 0,
      "z": -4,
      "name": "Deco_Bone_Full",
      "rotation": 5
    },
    {
      "x": 2,
      "y": 0,
      "z": -2,
      "name": "Deco_Bone_Full",
      "rotation": 5
    },
    {
      "x": 2,
      "y": 0,
      "z": 0,
      "name": "Deco_Bone_Full",
      "rotation": 5
    },
    {
      "x": 2,
      "y": 0,
      "z": 2,
      "name": "Deco_Bone_Full",
      "rotation": 5
    },
    {
      "x": 2,
      "y": 0,
      "z": 4,
      "name": "Deco_Bone_Full",
      "rotation": 5
    },
    {
      "x": 2,
      "y": 0,
      "z": 6,
      "name": "Deco_Bone_Full",
      "rotation": 5
    },
    {
      "x": 2,
      "y": 0,
      "z": 8,
      "name": "Deco_Bone_Full",
      "rotation": 5
    },
    {
      "x": 2,
      "y": 1,
      "z": 8,
      "name": "Deco_Bone_Full"
    },
    {
      "x": 2,
      "y": 2,
      "z": 8,
      "name": "Deco_Bone_Full"
    },
    {
      "x": 2,
      "y": 3,
      "z": 8,
      "name": "Deco_Bone_Ribs_Long"
    },
    {
      "x": 3,
      "y": 2,
      "z": -6,
      "name": "Deco_Bone_Full",
      "rotation": 5
    },
    {
      "x": 3,
      "y": 3,
      "z": -6,
      "name": "Deco_Bone_Full"
    },
    {
      "x": 3,
      "y": 4,
      "z": -6,
      "name": "Deco_Bone_Full"
    },
    {
      "x": 3,
      "y": 5,
      "z": -6,
      "name": "Deco_Bone_Ribs_Long"
    },
    {
      "x": 3,
      "y": 0,
      "z": -4,
      "name": "Deco_Bone_Full",
      "rotation": 5
    },
    {
      "x": 3,
      "y": 1,
      "z": -4,
      "name": "Deco_Bone_Full"
    },
    {
      "x": 3,
      "y": 2,
      "z": -4,
      "name": "Deco_Bone_Full"
    },
    {
      "x": 3,
      "y": 3,
      "z": -4,
      "name": "Deco_Bone_Ribs_Long"
    },
    {
      "x": 3,
      "y": 0,
      "z": -2,
      "name": "Deco_Bone_Full",
      "rotation": 5
    },
    {
      "x": 3,
      "y": 0,
      "z": 0,
      "name": "Deco_Bone_Full",
      "rotation": 5
    },
    {
      "x": 3,
      "y": 0,
      "z": 2,
      "name": "Deco_Bone_Full",
      "rotation": 5
    },
    {
      "x": 3,
      "y": 0,
      "z": 4,
      "name": "Deco_Bone_Full",
      "rotation": 5
    },
    {
      "x": 3,
      "y": 0,
      "z": 6,
      "name": "Deco_Bone_Full",
      "rotation": 5
    },
    {
      "x": 3,
      "y": 1,
      "z": 6,
      "name": "Deco_Bone_Full"
    },
    {
      "x": 3,
      "y": 2,
      "z": 6,
      "name": "Deco_Bone_Full"
    },
    {
      "x": 3,
      "y": 3,
      "z": 6,
      "name": "Deco_Bone_Ribs_Long"
    },
    {
      "x": 3,
      "y": 2,
      "z": 8,
      "name": "Deco_Bone_Full",
      "rotation": 5
    },
    {
      "x": 3,
      "y": 3,
      "z": 8,
      "name": "Deco_Bone_Full"
    },
    {
      "x": 3,
      "y": 4,
      "z": 8,
      "name": "Deco_Bone_Full"
    },
    {
      "x": 3,
      "y": 5,
      "z": 8,
      "name": "Deco_Bone_Ribs_Long"
    },
    {
      "x": 4,
      "y": 4,
      "z": -6,
      "name": "Deco_Bone_Full",
      "rotation": 5
    },
    {
      "x": 4,
      "y": 5,
      "z": -6,
      "name": "Deco_Bone_Full"
    },
    {
      "x": 4,
      "y": 6,
      "z": -6,
      "name": "Deco_Bone_Full"
    },
    {
      "x": 4,
      "y": 7,
      "z": -6,
      "name": "Deco_Bone_Ribs_Long"
    },
    {
      "x": 4,
      "y": 2,
      "z": -4,
      "name": "Deco_Bone_Full",
      "rotation": 5
    },
    {
      "x": 4,
      "y": 3,
      "z": -4,
      "name": "Deco_Bone_Full"
    },
    {
      "x": 4,
      "y": 4,
      "z": -4,
      "name": "Deco_Bone_Full"
    },
    {
      "x": 4,
      "y": 5,
      "z": -4,
      "name": "Deco_Bone_Full"
    },
    {
      "x": 4,
      "y": 6,
      "z": -4,
      "name": "Deco_Bone_Ribs_Long"
    },
    {
      "x": 4,
      "y": 0,
      "z": -2,
      "name": "Deco_Bone_Full",
      "rotation": 5
    },
    {
      "x": 4,
      "y": 1,
      "z": -2,
      "name": "Deco_Bone_Full"
    },
    {
      "x": 4,
      "y": 2,
      "z": -2,
      "name": "Deco_Bone_Full"
    },
    {
      "x": 4,
      "y": 3,
      "z": -2,
      "name": "Deco_Bone_Ribs_Long"
    },
    {
      "x": 4,
      "y": 0,
      "z": 0,
      "name": "Deco_Bone_Full",
      "rotation": 5
    },
    {
      "x": 4,
      "y": 0,
      "z": 2,
      "name": "Deco_Bone_Full",
      "rotation": 5
    },
    {
      "x": 4,
      "y": 1,
      "z": 2,
      "name": "Deco_Bone_Full"
    },
    {
      "x": 4,
      "y": 2,
      "z": 2,
      "name": "Deco_Bone_Full"
    },
    {
      "x": 4,
      "y": 3,
      "z": 2,
      "name": "Deco_Bone_Ribs_Long"
    },
    {
      "x": 4,
      "y": 0,
      "z": 4,
      "name": "Deco_Bone_Full",
      "rotation": 5
    },
    {
      "x": 4,
      "y": 1,
      "z": 4,
      "name": "Deco_Bone_Full"
    },
    {
      "x": 4,
      "y": 2,
      "z": 4,
      "name": "Deco_Bone_Full"
    },
    {
      "x": 4,
      "y": 3,
      "z": 4,
      "name": "Deco_Bone_Ribs_Long"
    },
    {
      "x": 4,
      "y": 2,
      "z": 6,
      "name": "Deco_Bone_Full",
      "rotation": 5
    },
    {
      "x": 4,
      "y": 3,
      "z": 6,
      "name": "Deco_Bone_Full"
    },
    {
      "x": 4,
      "y": 4,
      "z": 6,
      "name": "Deco_Bone_Full"
    },
    {
      "x": 4,
      "y": 5,
      "z": 6,
      "name": "Deco_Bone_Full"
    },
    {
      "x": 4,
      "y": 6,
      "z": 6,
      "name": "Deco_Bone_Ribs_Long"
    },
    {
      "x": 4,
      "y": 4,
      "z": 8,
      "name": "Deco_Bone_Full",
      "rotation": 5
    },
    {
      "x": 4,
      "y": 5,
      "z": 8,
      "name": "Deco_Bone_Full"
    },
    {
      "x": 4,
      "y": 6,
      "z": 8,
      "name": "Deco_Bone_Full"
    },
    {
      "x": 4,
      "y": 7,
      "z": 8,
      "name": "Deco_Bone_Ribs_Long"
    },
    {
      "x": 5,
      "y": 5,
      "z": -4,
      "name": "Deco_Bone_Full",
      "rotation": 5
    },
    {
      "x": 5,
      "y": 6,
      "z": -4,
      "name": "Deco_Bone_Full"
    },
    {
      "x": 5,
      "y": 7,
      "z": -4,
      "name": "Deco_Bone_Full"
    },
    {
      "x": 5,
      "y": 8,
      "z": -4,
      "name": "Deco_Bone_Ribs_Long"
    },
    {
      "x": 5,
      "y": 2,
      "z": -2,
      "name": "Deco_Bone_Full",
      "rotation": 5
    },
    {
      "x": 5,
      "y": 3,
      "z": -2,
      "name": "Deco_Bone_Full"
    },
    {
      "x": 5,
      "y": 4,
      "z": -2,
      "name": "Deco_Bone_Full"
    },
    {
      "x": 5,
      "y": 5,
      "z": -2,
      "name": "Deco_Bone_Full"
    },
    {
      "x": 5,
      "y": 6,
      "z": -2,
      "name": "Deco_Bone_Ribs_Long"
    },
    {
      "x": 5,
      "y": 0,
      "z": 0,
      "name": "Deco_Bone_Full",
      "rotation": 5
    },
    {
      "x": 5,
      "y": 1,
      "z": 0,
      "name": "Deco_Bone_Full"
    },
    {
      "x": 5,
      "y": 2,
      "z": 0,
      "name": "Deco_Bone_Full"
    },
    {
      "x": 5,
      "y": 3,
      "z": 0,
      "name": "Deco_Bone_Full"
    },
    {
      "x": 5,
      "y": 4,
      "z": 0,
      "name": "Deco_Bone_Ribs_Long"
    },
    {
      "x": 5,
      "y": 2,
      "z": 2,
      "name": "Deco_Bone_Full",
      "rotation": 5
    },
    {
      "x": 5,
      "y": 3,
      "z": 2,
      "name": "Deco_Bone_Full"
    },
    {
      "x": 5,
      "y": 4,
      "z": 2,
      "name": "Deco_Bone_Full"
    },
    {
      "x": 5,
      "y": 5,
      "z": 2,
      "name": "Deco_Bone_Full"
    },
    {
      "x": 5,
      "y": 6,
      "z": 2,
      "name": "Deco_Bone_Ribs_Long"
    },
    {
      "x": 5,
      "y": 2,
      "z": 4,
      "name": "Deco_Bone_Full",
      "rotation": 5
    },
    {
      "x": 5,
      "y": 3,
      "z": 4,
      "name": "Deco_Bone_Full"
    },
    {
      "x": 5,
      "y": 4,
      "z": 4,
      "name": "Deco_Bone_Full"
    },
    {
      "x": 5,
      "y": 5,
      "z": 4,
      "name": "Deco_Bone_Full"
    },
    {
      "x": 5,
      "y": 6,
      "z": 4,
      "name": "Deco_Bone_Ribs_Long"
    },
    {
      "x": 5,
      "y": 5,
      "z": 6,
      "name": "Deco_Bone_Full",
      "rotation": 5
    },
    {
      "x": 5,
      "y": 6,
      "z": 6,
      "name": "Deco_Bone_Full"
    },
    {
      "x": 5,
      "y": 7,
      "z": 6,
      "name": "Deco_Bone_Full"
    },
    {
      "x": 5,
      "y": 8,
      "z": 6,
      "name": "Deco_Bone_Ribs_Long"
    },
    {
      "x": 6,
      "y": 5,
      "z": -2,
      "name": "Deco_Bone_Full",
      "rotation": 5
    },
    {
      "x": 6,
      "y": 6,
      "z": -2,
      "name": "Deco_Bone_Full"
    },
    {
      "x": 6,
      "y": 7,
      "z": -2,
      "name": "Deco_Bone_Full"
    },
    {
      "x": 6,
      "y": 8,
      "z": -2,
      "name": "Deco_Bone_Full"
    },
    {
      "x": 6,
      "y": 9,
      "z": -2,
      "name": "Deco_Bone_Ribs_Long"
    },
    {
      "x": 6,
      "y": 3,
      "z": 0,
      "name": "Deco_Bone_Full",
      "rotation": 5
    },
    {
      "x": 6,
      "y": 4,
      "z": 0,
      "name": "Deco_Bone_Full"
    },
    {
      "x": 6,
      "y": 5,
      "z": 0,
      "name": "Deco_Bone_Full"
    },
    {
      "x": 6,
      "y": 6,
      "z": 0,
      "name": "Deco_Bone_Full"
    },
    {
      "x": 6,
      "y": 7,
      "z": 0,
      "name": "Deco_Bone_Ribs_Long"
    },
    {
      "x": 6,
      "y": 5,
      "z": 2,
      "name": "Deco_Bone_Full",
      "rotation": 5
    },
    {
      "x": 6,
      "y": 6,
      "z": 2,
      "name": "Deco_Bone_Full"
    },
    {
      "x": 6,
      "y": 7,
      "z": 2,
      "name": "Deco_Bone_Full"
    },
    {
      "x": 6,
      "y": 8,
      "z": 2,
      "name": "Deco_Bone_Full"
    },
    {
      "x": 6,
      "y": 9,
      "z": 2,
      "name": "Deco_Bone_Ribs_Long"
    },
    {
      "x": 6,
      "y": 5,
      "z": 4,
      "name": "Deco_Bone_Full",
      "rotation": 5
    },
    {
      "x": 6,
      "y": 6,
      "z": 4,
      "name": "Deco_Bone_Full"
    },
    {
      "x": 6,
      "y": 7,
      "z": 4,
      "name": "Deco_Bone_Full"
    },
    {
      "x": 6,
      "y": 8,
      "z": 4,
      "name": "Deco_Bone_Full"
    },
    {
      "x": 6,
      "y": 9,
      "z": 4,
      "name": "Deco_Bone_Ribs_Long"
    },
    {
      "x": 7,
      "y": 6,
      "z": 0,
      "name": "Deco_Bone_Full",
      "rotation": 5
    },
    {
      "x": 7,
      "y": 7,
      "z": 0,
      "name": "Deco_Bone_Full"
    },
    {
      "x": 7,
      "y": 8,
      "z": 0,
      "name": "Deco_Bone_Full"
    },
    {
      "x": 7,
      "y": 9,
      "z": 0,
      "name": "Deco_Bone_Full"
    },
    {
      "x": 7,
      "y": 10,
      "z": 0,
      "name": "Deco_Bone_Ribs_Long"
    }
  ],
  "fluids": [
    {
      "x": -7,
      "y": 6,
      "z": 0,
      "name": "Empty",
      "level": 0
    },
    {
      "x": -7,
      "y": 7,
      "z": 0,
      "name": "Empty",
      "level": 0
    },
    {
      "x": -7,
      "y": 8,
      "z": 0,
      "name": "Empty",
      "level": 0
    },
    {
      "x": -7,
      "y": 9,
      "z": 0,
      "name": "Empty",
      "level": 0
    },
    {
      "x": -7,
      "y": 10,
      "z": 0,
      "name": "Empty",
      "level": 0
    },
    {
      "x": -6,
      "y": 5,
      "z": -2,
      "name": "Empty",
      "level": 0
    },
    {
      "x": -6,
      "y": 6,
      "z": -2,
      "name": "Empty",
      "level": 0
    },
    {
      "x": -6,
      "y": 7,
      "z": -2,
      "name": "Empty",
      "level": 0
    },
    {
      "x": -6,
      "y": 8,
      "z": -2,
      "name": "Empty",
      "level": 0
    },
    {
      "x": -6,
      "y": 9,
      "z": -2,
      "name": "Empty",
      "level": 0
    },
    {
      "x": -6,
      "y": 3,
      "z": 0,
      "name": "Empty",
      "level": 0
    },
    {
      "x": -6,
      "y": 4,
      "z": 0,
      "name": "Empty",
      "level": 0
    },
    {
      "x": -6,
      "y": 5,
      "z": 0,
      "name": "Empty",
      "level": 0
    },
    {
      "x": -6,
      "y": 6,
      "z": 0,
      "name": "Empty",
      "level": 0
    },
    {
      "x": -6,
      "y": 7,
      "z": 0,
      "name": "Empty",
      "level": 0
    },
    {
      "x": -6,
      "y": 5,
      "z": 2,
      "name": "Empty",
      "level": 0
    },
    {
      "x": -6,
      "y": 6,
      "z": 2,
      "name": "Empty",
      "level": 0
    },
    {
      "x": -6,
      "y": 7,
      "z": 2,
      "name": "Empty",
      "level": 0
    },
    {
      "x": -6,
      "y": 8,
      "z": 2,
      "name": "Empty",
      "level": 0
    },
    {
      "x": -6,
      "y": 9,
      "z": 2,
      "name": "Empty",
      "level": 0
    },
    {
      "x": -6,
      "y": 5,
      "z": 4,
      "name": "Empty",
      "level": 0
    },
    {
      "x": -6,
      "y": 6,
      "z": 4,
      "name": "Empty",
      "level": 0
    },
    {
      "x": -6,
      "y": 7,
      "z": 4,
      "name": "Empty",
      "level": 0
    },
    {
      "x": -6,
      "y": 8,
      "z": 4,
      "name": "Empty",
      "level": 0
    },
    {
      "x": -6,
      "y": 9,
      "z": 4,
      "name": "Empty",
      "level": 0
    },
    {
      "x": -5,
      "y": 5,
      "z": -4,
      "name": "Empty",
      "level": 0
    },
    {
      "x": -5,
      "y": 6,
      "z": -4,
      "name": "Empty",
      "level": 0
    },
    {
      "x": -5,
      "y": 7,
      "z": -4,
      "name": "Empty",
      "level": 0
    },
    {
      "x": -5,
      "y": 8,
      "z": -4,
      "name": "Empty",
      "level": 0
    },
    {
      "x": -5,
      "y": 9,
      "z": -4,
      "name": "Empty",
      "level": 0
    },
    {
      "x": -5,
      "y": 2,
      "z": -2,
      "name": "Empty",
      "level": 0
    },
    {
      "x": -5,
      "y": 3,
      "z": -2,
      "name": "Empty",
      "level": 0
    },
    {
      "x": -5,
      "y": 4,
      "z": -2,
      "name": "Empty",
      "level": 0
    },
    {
      "x": -5,
      "y": 5,
      "z": -2,
      "name": "Empty",
      "level": 0
    },
    {
      "x": -5,
      "y": 6,
      "z": -2,
      "name": "Empty",
      "level": 0
    },
    {
      "x": -5,
      "y": 0,
      "z": 0,
      "name": "Empty",
      "level": 0
    },
    {
      "x": -5,
      "y": 1,
      "z": 0,
      "name": "Empty",
      "level": 0
    },
    {
      "x": -5,
      "y": 2,
      "z": 0,
      "name": "Empty",
      "level": 0
    },
    {
      "x": -5,
      "y": 3,
      "z": 0,
      "name": "Empty",
      "level": 0
    },
    {
      "x": -5,
      "y": 4,
      "z": 0,
      "name": "Empty",
      "level": 0
    },
    {
      "x": -5,
      "y": 2,
      "z": 2,
      "name": "Empty",
      "level": 0
    },
    {
      "x": -5,
      "y": 3,
      "z": 2,
      "name": "Empty",
      "level": 0
    },
    {
      "x": -5,
      "y": 4,
      "z": 2,
      "name": "Empty",
      "level": 0
    },
    {
      "x": -5,
      "y": 5,
      "z": 2,
      "name": "Empty",
      "level": 0
    },
    {
      "x": -5,
      "y": 6,
      "z": 2,
      "name": "Empty",
      "level": 0
    },
    {
      "x": -5,
      "y": 2,
      "z": 4,
      "name": "Empty",
      "level": 0
    },
    {
      "x": -5,
      "y": 3,
      "z": 4,
      "name": "Empty",
      "level": 0
    },
    {
      "x": -5,
      "y": 4,
      "z": 4,
      "name": "Empty",
      "level": 0
    },
    {
      "x": -5,
      "y": 5,
      "z": 4,
      "name": "Empty",
      "level": 0
    },
    {
      "x": -5,
      "y": 6,
      "z": 4,
      "name": "Empty",
      "level": 0
    },
    {
      "x": -5,
      "y": 5,
      "z": 6,
      "name": "Empty",
      "level": 0
    },
    {
      "x": -5,
      "y": 6,
      "z": 6,
      "name": "Empty",
      "level": 0
    },
    {
      "x": -5,
      "y": 7,
      "z": 6,
      "name": "Empty",
      "level": 0
    },
    {
      "x": -5,
      "y": 8,
      "z": 6,
      "name": "Empty",
      "level": 0
    },
    {
      "x": -4,
      "y": 4,
      "z": -6,
      "name": "Empty",
      "level": 0
    },
    {
      "x": -4,
      "y": 5,
      "z": -6,
      "name": "Empty",
      "level": 0
    },
    {
      "x": -4,
      "y": 6,
      "z": -6,
      "name": "Empty",
      "level": 0
    },
    {
      "x": -4,
      "y": 7,
      "z": -6,
      "name": "Empty",
      "level": 0
    },
    {
      "x": -4,
      "y": 2,
      "z": -4,
      "name": "Empty",
      "level": 0
    },
    {
      "x": -4,
      "y": 3,
      "z": -4,
      "name": "Empty",
      "level": 0
    },
    {
      "x": -4,
      "y": 4,
      "z": -4,
      "name": "Empty",
      "level": 0
    },
    {
      "x": -4,
      "y": 5,
      "z": -4,
      "name": "Empty",
      "level": 0
    },
    {
      "x": -4,
      "y": 6,
      "z": -4,
      "name": "Empty",
      "level": 0
    },
    {
      "x": -4,
      "y": 0,
      "z": -2,
      "name": "Empty",
      "level": 0
    },
    {
      "x": -4,
      "y": 1,
      "z": -2,
      "name": "Empty",
      "level": 0
    },
    {
      "x": -4,
      "y": 2,
      "z": -2,
      "name": "Empty",
      "level": 0
    },
    {
      "x": -4,
      "y": 3,
      "z": -2,
      "name": "Empty",
      "level": 0
    },
    {
      "x": -4,
      "y": 0,
      "z": 0,
      "name": "Empty",
      "level": 0
    },
    {
      "x": -4,
      "y": 0,
      "z": 2,
      "name": "Empty",
      "level": 0
    },
    {
      "x": -4,
      "y": 1,
      "z": 2,
      "name": "Empty",
      "level": 0
    },
    {
      "x": -4,
      "y": 2,
      "z": 2,
      "name": "Empty",
      "level": 0
    },
    {
      "x": -4,
      "y": 3,
      "z": 2,
      "name": "Empty",
      "level": 0
    },
    {
      "x": -4,
      "y": 0,
      "z": 4,
      "name": "Empty",
      "level": 0
    },
    {
      "x": -4,
      "y": 1,
      "z": 4,
      "name": "Empty",
      "level": 0
    },
    {
      "x": -4,
      "y": 2,
      "z": 4,
      "name": "Empty",
      "level": 0
    },
    {
      "x": -4,
      "y": 3,
      "z": 4,
      "name": "Empty",
      "level": 0
    },
    {
      "x": -4,
      "y": 2,
      "z": 6,
      "name": "Empty",
      "level": 0
    },
    {
      "x": -4,
      "y": 3,
      "z": 6,
      "name": "Empty",
      "level": 0
    },
    {
      "x": -4,
      "y": 4,
      "z": 6,
      "name": "Empty",
      "level": 0
    },
    {
      "x": -4,
      "y": 5,
      "z": 6,
      "name": "Empty",
      "level": 0
    },
    {
      "x": -4,
      "y": 6,
      "z": 6,
      "name": "Empty",
      "level": 0
    },
    {
      "x": -4,
      "y": 4,
      "z": 8,
      "name": "Empty",
      "level": 0
    },
    {
      "x": -4,
      "y": 5,
      "z": 8,
      "name": "Empty",
      "level": 0
    },
    {
      "x": -4,
      "y": 6,
      "z": 8,
      "name": "Empty",
      "level": 0
    },
    {
      "x": -4,
      "y": 7,
      "z": 8,
      "name": "Empty",
      "level": 0
    },
    {
      "x": -3,
      "y": 2,
      "z": -6,
      "name": "Empty",
      "level": 0
    },
    {
      "x": -3,
      "y": 3,
      "z": -6,
      "name": "Empty",
      "level": 0
    },
    {
      "x": -3,
      "y": 4,
      "z": -6,
      "name": "Empty",
      "level": 0
    },
    {
      "x": -3,
      "y": 5,
      "z": -6,
      "name": "Empty",
      "level": 0
    },
    {
      "x": -3,
      "y": 0,
      "z": -4,
      "name": "Empty",
      "level": 0
    },
    {
      "x": -3,
      "y": 1,
      "z": -4,
      "name": "Empty",
      "level": 0
    },
    {
      "x": -3,
      "y": 2,
      "z": -4,
      "name": "Empty",
      "level": 0
    },
    {
      "x": -3,
      "y": 3,
      "z": -4,
      "name": "Empty",
      "level": 0
    },
    {
      "x": -3,
      "y": 0,
      "z": -2,
      "name": "Empty",
      "level": 0
    },
    {
      "x": -3,
      "y": 0,
      "z": 0,
      "name": "Empty",
      "level": 0
    },
    {
      "x": -3,
      "y": 0,
      "z": 2,
      "name": "Empty",
      "level": 0
    },
    {
      "x": -3,
      "y": 0,
      "z": 4,
      "name": "Empty",
      "level": 0
    },
    {
      "x": -3,
      "y": 0,
      "z": 6,
      "name": "Empty",
      "level": 0
    },
    {
      "x": -3,
      "y": 1,
      "z": 6,
      "name": "Empty",
      "level": 0
    },
    {
      "x": -3,
      "y": 2,
      "z": 6,
      "name": "Empty",
      "level": 0
    },
    {
      "x": -3,
      "y": 3,
      "z": 6,
      "name": "Empty",
      "level": 0
    },
    {
      "x": -3,
      "y": 2,
      "z": 8,
      "name": "Empty",
      "level": 0
    },
    {
      "x": -3,
      "y": 3,
      "z": 8,
      "name": "Empty",
      "level": 0
    },
    {
      "x": -3,
      "y": 4,
      "z": 8,
      "name": "Empty",
      "level": 0
    },
    {
      "x": -3,
      "y": 5,
      "z": 8,
      "name": "Empty",
      "level": 0
    },
    {
      "x": -2,
      "y": 0,
      "z": -6,
      "name": "Empty",
      "level": 0
    },
    {
      "x": -2,
      "y": 1,
      "z": -6,
      "name": "Empty",
      "level": 0
    },
    {
      "x": -2,
      "y": 2,
      "z": -6,
      "name": "Empty",
      "level": 0
    },
    {
      "x": -2,
      "y": 3,
      "z": -6,
      "name": "Empty",
      "level": 0
    },
    {
      "x": -2,
      "y": 0,
      "z": -4,
      "name": "Empty",
      "level": 0
    },
    {
      "x": -2,
      "y": 0,
      "z": -2,
      "name": "Empty",
      "level": 0
    },
    {
      "x": -2,
      "y": 0,
      "z": 0,
      "name": "Empty",
      "level": 0
    },
    {
      "x": -2,
      "y": 0,
      "z": 2,
      "name": "Empty",
      "level": 0
    },
    {
      "x": -2,
      "y": 0,
      "z": 4,
      "name": "Empty",
      "level": 0
    },
    {
      "x": -2,
      "y": 0,
      "z": 6,
      "name": "Empty",
      "level": 0
    },
    {
      "x": -2,
      "y": 0,
      "z": 8,
      "name": "Empty",
      "level": 0
    },
    {
      "x": -2,
      "y": 1,
      "z": 8,
      "name": "Empty",
      "level": 0
    },
    {
      "x": -2,
      "y": 2,
      "z": 8,
      "name": "Empty",
      "level": 0
    },
    {
      "x": -2,
      "y": 3,
      "z": 8,
      "name": "Empty",
      "level": 0
    },
    {
      "x": -1,
      "y": 0,
      "z": -6,
      "name": "Empty",
      "level": 0
    },
    {
      "x": -1,
      "y": 0,
      "z": -4,
      "name": "Empty",
      "level": 0
    },
    {
      "x": -1,
      "y": 0,
      "z": -2,
      "name": "Empty",
      "level": 0
    },
    {
      "x": -1,
      "y": 0,
      "z": 0,
      "name": "Empty",
      "level": 0
    },
    {
      "x": -1,
      "y": 0,
      "z": 2,
      "name": "Empty",
      "level": 0
    },
    {
      "x": -1,
      "y": 0,
      "z": 4,
      "name": "Empty",
      "level": 0
    },
    {
      "x": -1,
      "y": 0,
      "z": 6,
      "name": "Empty",
      "level": 0
    },
    {
      "x": -1,
      "y": 0,
      "z": 8,
      "name": "Empty",
      "level": 0
    },
    {
      "x": 0,
      "y": 2,
      "z": -11,
      "name": "Empty",
      "level": 0
    },
    {
      "x": 0,
      "y": 3,
      "z": -11,
      "name": "Empty",
      "level": 0
    },
    {
      "x": 0,
      "y": 1,
      "z": -10,
      "name": "Empty",
      "level": 0
    },
    {
      "x": 0,
      "y": 2,
      "z": -10,
      "name": "Empty",
      "level": 0
    },
    {
      "x": 0,
      "y": 3,
      "z": -10,
      "name": "Empty",
      "level": 0
    },
    {
      "x": 0,
      "y": 4,
      "z": -10,
      "name": "Empty",
      "level": 0
    },
    {
      "x": 0,
      "y": 1,
      "z": -9,
      "name": "Empty",
      "level": 0
    },
    {
      "x": 0,
      "y": 2,
      "z": -9,
      "name": "Empty",
      "level": 0
    },
    {
      "x": 0,
      "y": 3,
      "z": -9,
      "name": "Empty",
      "level": 0
    },
    {
      "x": 0,
      "y": 0,
      "z": -8,
      "name": "Empty",
      "level": 0
    },
    {
      "x": 0,
      "y": 1,
      "z": -8,
      "name": "Empty",
      "level": 0
    },
    {
      "x": 0,
      "y": 2,
      "z": -8,
      "name": "Empty",
      "level": 0
    },
    {
      "x": 0,
      "y": 3,
      "z": -8,
      "name": "Empty",
      "level": 0
    },
    {
      "x": 0,
      "y": 0,
      "z": -7,
      "name": "Empty",
      "level": 0
    },
    {
      "x": 0,
      "y": 1,
      "z": -7,
      "name": "Empty",
      "level": 0
    },
    {
      "x": 0,
      "y": 2,
      "z": -7,
      "name": "Empty",
      "level": 0
    },
    {
      "x": 0,
      "y": 0,
      "z": -6,
      "name": "Empty",
      "level": 0
    },
    {
      "x": 0,
      "y": 1,
      "z": -6,
      "name": "Empty",
      "level": 0
    },
    {
      "x": 0,
      "y": 2,
      "z": -6,
      "name": "Empty",
      "level": 0
    },
    {
      "x": 0,
      "y": 0,
      "z": -5,
      "name": "Empty",
      "level": 0
    },
    {
      "x": 0,
      "y": 1,
      "z": -5,
      "name": "Empty",
      "level": 0
    },
    {
      "x": 0,
      "y": 0,
      "z": -4,
      "name": "Empty",
      "level": 0
    },
    {
      "x": 0,
      "y": 1,
      "z": -4,
      "name": "Empty",
      "level": 0
    },
    {
      "x": 0,
      "y": 0,
      "z": -3,
      "name": "Empty",
      "level": 0
    },
    {
      "x": 0,
      "y": 1,
      "z": -3,
      "name": "Empty",
      "level": 0
    },
    {
      "x": 0,
      "y": 0,
      "z": -2,
      "name": "Empty",
      "level": 0
    },
    {
      "x": 0,
      "y": 1,
      "z": -2,
      "name": "Empty",
      "level": 0
    },
    {
      "x": 0,
      "y": 0,
      "z": -1,
      "name": "Empty",
      "level": 0
    },
    {
      "x": 0,
      "y": 1,
      "z": -1,
      "name": "Empty",
      "level": 0
    },
    {
      "x": 0,
      "y": 0,
      "z": 0,
      "name": "Empty",
      "level": 0
    },
    {
      "x": 0,
      "y": 1,
      "z": 0,
      "name": "Empty",
      "level": 0
    },
    {
      "x": 0,
      "y": 0,
      "z": 1,
      "name": "Empty",
      "level": 0
    },
    {
      "x": 0,
      "y": 1,
      "z": 1,
      "name": "Empty",
      "level": 0
    },
    {
      "x": 0,
      "y": 0,
      "z": 2,
      "name": "Empty",
      "level": 0
    },
    {
      "x": 0,
      "y": 1,
      "z": 2,
      "name": "Empty",
      "level": 0
    },
    {
      "x": 0,
      "y": 0,
      "z": 3,
      "name": "Empty",
      "level": 0
    },
    {
      "x": 0,
      "y": 1,
      "z": 3,
      "name": "Empty",
      "level": 0
    },
    {
      "x": 0,
      "y": 0,
      "z": 4,
      "name": "Empty",
      "level": 0
    },
    {
      "x": 0,
      "y": 1,
      "z": 4,
      "name": "Empty",
      "level": 0
    },
    {
      "x": 0,
      "y": 0,
      "z": 5,
      "name": "Empty",
      "level": 0
    },
    {
      "x": 0,
      "y": 1,
      "z": 5,
      "name": "Empty",
      "level": 0
    },
    {
      "x": 0,
      "y": 0,
      "z": 6,
      "name": "Empty",
      "level": 0
    },
    {
      "x": 0,
      "y": 1,
      "z": 6,
      "name": "Empty",
      "level": 0
    },
    {
      "x": 0,
      "y": 0,
      "z": 7,
      "name": "Empty",
      "level": 0
    },
    {
      "x": 0,
      "y": 1,
      "z": 7,
      "name": "Empty",
      "level": 0
    },
    {
      "x": 0,
      "y": 0,
      "z": 8,
      "name": "Empty",
      "level": 0
    },
    {
      "x": 0,
      "y": 1,
      "z": 8,
      "name": "Empty",
      "level": 0
    },
    {
      "x": 0,
      "y": 2,
      "z": 8,
      "name": "Empty",
      "level": 0
    },
    {
      "x": 0,
      "y": 0,
      "z": 9,
      "name": "Empty",
      "level": 0
    },
    {
      "x": 0,
      "y": 1,
      "z": 9,
      "name": "Empty",
      "level": 0
    },
    {
      "x": 0,
      "y": 2,
      "z": 9,
      "name": "Empty",
      "level": 0
    },
    {
      "x": 0,
      "y": 0,
      "z": 10,
      "name": "Empty",
      "level": 0
    },
    {
      "x": 0,
      "y": 1,
      "z": 10,
      "name": "Empty",
      "level": 0
    },
    {
      "x": 0,
      "y": 2,
      "z": 10,
      "name": "Empty",
      "level": 0
    },
    {
      "x": 0,
      "y": 3,
      "z": 10,
      "name": "Empty",
      "level": 0
    },
    {
      "x": 0,
      "y": 1,
      "z": 11,
      "name": "Empty",
      "level": 0
    },
    {
      "x": 0,
      "y": 2,
      "z": 11,
      "name": "Empty",
      "level": 0
    },
    {
      "x": 1,
      "y": 0,
      "z": -6,
      "name": "Empty",
      "level": 0
    },
    {
      "x": 1,
      "y": 0,
      "z": -4,
      "name": "Empty",
      "level": 0
    },
    {
      "x": 1,
      "y": 0,
      "z": -2,
      "name": "Empty",
      "level": 0
    },
    {
      "x": 1,
      "y": 0,
      "z": 0,
      "name": "Empty",
      "level": 0
    },
    {
      "x": 1,
      "y": 0,
      "z": 2,
      "name": "Empty",
      "level": 0
    },
    {
      "x": 1,
      "y": 0,
      "z": 4,
      "name": "Empty",
      "level": 0
    },
    {
      "x": 1,
      "y": 0,
      "z": 6,
      "name": "Empty",
      "level": 0
    },
    {
      "x": 1,
      "y": 0,
      "z": 8,
      "name": "Empty",
      "level": 0
    },
    {
      "x": 2,
      "y": 0,
      "z": -6,
      "name": "Empty",
      "level": 0
    },
    {
      "x": 2,
      "y": 1,
      "z": -6,
      "name": "Empty",
      "level": 0
    },
    {
      "x": 2,
      "y": 2,
      "z": -6,
      "name": "Empty",
      "level": 0
    },
    {
      "x": 2,
      "y": 3,
      "z": -6,
      "name": "Empty",
      "level": 0
    },
    {
      "x": 2,
      "y": 0,
      "z": -4,
      "name": "Empty",
      "level": 0
    },
    {
      "x": 2,
      "y": 0,
      "z": -2,
      "name": "Empty",
      "level": 0
    },
    {
      "x": 2,
      "y": 0,
      "z": 0,
      "name": "Empty",
      "level": 0
    },
    {
      "x": 2,
      "y": 0,
      "z": 2,
      "name": "Empty",
      "level": 0
    },
    {
      "x": 2,
      "y": 0,
      "z": 4,
      "name": "Empty",
      "level": 0
    },
    {
      "x": 2,
      "y": 0,
      "z": 6,
      "name": "Empty",
      "level": 0
    },
    {
      "x": 2,
      "y": 0,
      "z": 8,
      "name": "Empty",
      "level": 0
    },
    {
      "x": 2,
      "y": 1,
      "z": 8,
      "name": "Empty",
      "level": 0
    },
    {
      "x": 2,
      "y": 2,
      "z": 8,
      "name": "Empty",
      "level": 0
    },
    {
      "x": 2,
      "y": 3,
      "z": 8,
      "name": "Empty",
      "level": 0
    },
    {
      "x": 3,
      "y": 2,
      "z": -6,
      "name": "Empty",
      "level": 0
    },
    {
      "x": 3,
      "y": 3,
      "z": -6,
      "name": "Empty",
      "level": 0
    },
    {
      "x": 3,
      "y": 4,
      "z": -6,
      "name": "Empty",
      "level": 0
    },
    {
      "x": 3,
      "y": 5,
      "z": -6,
      "name": "Empty",
      "level": 0
    },
    {
      "x": 3,
      "y": 0,
      "z": -4,
      "name": "Empty",
      "level": 0
    },
    {
      "x": 3,
      "y": 1,
      "z": -4,
      "name": "Empty",
      "level": 0
    },
    {
      "x": 3,
      "y": 2,
      "z": -4,
      "name": "Empty",
      "level": 0
    },
    {
      "x": 3,
      "y": 3,
      "z": -4,
      "name": "Empty",
      "level": 0
    },
    {
      "x": 3,
      "y": 0,
      "z": -2,
      "name": "Empty",
      "level": 0
    },
    {
      "x": 3,
      "y": 0,
      "z": 0,
      "name": "Empty",
      "level": 0
    },
    {
      "x": 3,
      "y": 0,
      "z": 2,
      "name": "Empty",
      "level": 0
    },
    {
      "x": 3,
      "y": 0,
      "z": 4,
      "name": "Empty",
      "level": 0
    },
    {
      "x": 3,
      "y": 0,
      "z": 6,
      "name": "Empty",
      "level": 0
    },
    {
      "x": 3,
      "y": 1,
      "z": 6,
      "name": "Empty",
      "level": 0
    },
    {
      "x": 3,
      "y": 2,
      "z": 6,
      "name": "Empty",
      "level": 0
    },
    {
      "x": 3,
      "y": 3,
      "z": 6,
      "name": "Empty",
      "level": 0
    },
    {
      "x": 3,
      "y": 2,
      "z": 8,
      "name": "Empty",
      "level": 0
    },
    {
      "x": 3,
      "y": 3,
      "z": 8,
      "name": "Empty",
      "level": 0
    },
    {
      "x": 3,
      "y": 4,
      "z": 8,
      "name": "Empty",
      "level": 0
    },
    {
      "x": 3,
      "y": 5,
      "z": 8,
      "name": "Empty",
      "level": 0
    },
    {
      "x": 4,
      "y": 4,
      "z": -6,
      "name": "Empty",
      "level": 0
    },
    {
      "x": 4,
      "y": 5,
      "z": -6,
      "name": "Empty",
      "level": 0
    },
    {
      "x": 4,
      "y": 6,
      "z": -6,
      "name": "Empty",
      "level": 0
    },
    {
      "x": 4,
      "y": 7,
      "z": -6,
      "name": "Empty",
      "level": 0
    },
    {
      "x": 4,
      "y": 2,
      "z": -4,
      "name": "Empty",
      "level": 0
    },
    {
      "x": 4,
      "y": 3,
      "z": -4,
      "name": "Empty",
      "level": 0
    },
    {
      "x": 4,
      "y": 4,
      "z": -4,
      "name": "Empty",
      "level": 0
    },
    {
      "x": 4,
      "y": 5,
      "z": -4,
      "name": "Empty",
      "level": 0
    },
    {
      "x": 4,
      "y": 6,
      "z": -4,
      "name": "Empty",
      "level": 0
    },
    {
      "x": 4,
      "y": 0,
      "z": -2,
      "name": "Empty",
      "level": 0
    },
    {
      "x": 4,
      "y": 1,
      "z": -2,
      "name": "Empty",
      "level": 0
    },
    {
      "x": 4,
      "y": 2,
      "z": -2,
      "name": "Empty",
      "level": 0
    },
    {
      "x": 4,
      "y": 3,
      "z": -2,
      "name": "Empty",
      "level": 0
    },
    {
      "x": 4,
      "y": 0,
      "z": 0,
      "name": "Empty",
      "level": 0
    },
    {
      "x": 4,
      "y": 0,
      "z": 2,
      "name": "Empty",
      "level": 0
    },
    {
      "x": 4,
      "y": 1,
      "z": 2,
      "name": "Empty",
      "level": 0
    },
    {
      "x": 4,
      "y": 2,
      "z": 2,
      "name": "Empty",
      "level": 0
    },
    {
      "x": 4,
      "y": 3,
      "z": 2,
      "name": "Empty",
      "level": 0
    },
    {
      "x": 4,
      "y": 0,
      "z": 4,
      "name": "Empty",
      "level": 0
    },
    {
      "x": 4,
      "y": 1,
      "z": 4,
      "name": "Empty",
      "level": 0
    },
    {
      "x": 4,
      "y": 2,
      "z": 4,
      "name": "Empty",
      "level": 0
    },
    {
      "x": 4,
      "y": 3,
      "z": 4,
      "name": "Empty",
      "level": 0
    },
    {
      "x": 4,
      "y": 2,
      "z": 6,
      "name": "Empty",
      "level": 0
    },
    {
      "x": 4,
      "y": 3,
      "z": 6,
      "name": "Empty",
      "level": 0
    },
    {
      "x": 4,
      "y": 4,
      "z": 6,
      "name": "Empty",
      "level": 0
    },
    {
      "x": 4,
      "y": 5,
      "z": 6,
      "name": "Empty",
      "level": 0
    },
    {
      "x": 4,
      "y": 6,
      "z": 6,
      "name": "Empty",
      "level": 0
    },
    {
      "x": 4,
      "y": 4,
      "z": 8,
      "name": "Empty",
      "level": 0
    },
    {
      "x": 4,
      "y": 5,
      "z": 8,
      "name": "Empty",
      "level": 0
    },
    {
      "x": 4,
      "y": 6,
      "z": 8,
      "name": "Empty",
      "level": 0
    },
    {
      "x": 4,
      "y": 7,
      "z": 8,
      "name": "Empty",
      "level": 0
    },
    {
      "x": 5,
      "y": 5,
      "z": -4,
      "name": "Empty",
      "level": 0
    },
    {
      "x": 5,
      "y": 6,
      "z": -4,
      "name": "Empty",
      "level": 0
    },
    {
      "x": 5,
      "y": 7,
      "z": -4,
      "name": "Empty",
      "level": 0
    },
    {
      "x": 5,
      "y": 8,
      "z": -4,
      "name": "Empty",
      "level": 0
    },
    {
      "x": 5,
      "y": 2,
      "z": -2,
      "name": "Empty",
      "level": 0
    },
    {
      "x": 5,
      "y": 3,
      "z": -2,
      "name": "Empty",
      "level": 0
    },
    {
      "x": 5,
      "y": 4,
      "z": -2,
      "name": "Empty",
      "level": 0
    },
    {
      "x": 5,
      "y": 5,
      "z": -2,
      "name": "Empty",
      "level": 0
    },
    {
      "x": 5,
      "y": 6,
      "z": -2,
      "name": "Empty",
      "level": 0
    },
    {
      "x": 5,
      "y": 0,
      "z": 0,
      "name": "Empty",
      "level": 0
    },
    {
      "x": 5,
      "y": 1,
      "z": 0,
      "name": "Empty",
      "level": 0
    },
    {
      "x": 5,
      "y": 2,
      "z": 0,
      "name": "Empty",
      "level": 0
    },
    {
      "x": 5,
      "y": 3,
      "z": 0,
      "name": "Empty",
      "level": 0
    },
    {
      "x": 5,
      "y": 4,
      "z": 0,
      "name": "Empty",
      "level": 0
    },
    {
      "x": 5,
      "y": 2,
      "z": 2,
      "name": "Empty",
      "level": 0
    },
    {
      "x": 5,
      "y": 3,
      "z": 2,
      "name": "Empty",
      "level": 0
    },
    {
      "x": 5,
      "y": 4,
      "z": 2,
      "name": "Empty",
      "level": 0
    },
    {
      "x": 5,
      "y": 5,
      "z": 2,
      "name": "Empty",
      "level": 0
    },
    {
      "x": 5,
      "y": 6,
      "z": 2,
      "name": "Empty",
      "level": 0
    },
    {
      "x": 5,
      "y": 2,
      "z": 4,
      "name": "Empty",
      "level": 0
    },
    {
      "x": 5,
      "y": 3,
      "z": 4,
      "name": "Empty",
      "level": 0
    },
    {
      "x": 5,
      "y": 4,
      "z": 4,
      "name": "Empty",
      "level": 0
    },
    {
      "x": 5,
      "y": 5,
      "z": 4,
      "name": "Empty",
      "level": 0
    },
    {
      "x": 5,
      "y": 6,
      "z": 4,
      "name": "Empty",
      "level": 0
    },
    {
      "x": 5,
      "y": 5,
      "z": 6,
      "name": "Empty",
      "level": 0
    },
    {
      "x": 5,
      "y": 6,
      "z": 6,
      "name": "Empty",
      "level": 0
    },
    {
      "x": 5,
      "y": 7,
      "z": 6,
      "name": "Empty",
      "level": 0
    },
    {
      "x": 5,
      "y": 8,
      "z": 6,
      "name": "Empty",
      "level": 0
    },
    {
      "x": 6,
      "y": 5,
      "z": -2,
      "name": "Empty",
      "level": 0
    },
    {
      "x": 6,
      "y": 6,
      "z": -2,
      "name": "Empty",
      "level": 0
    },
    {
      "x": 6,
      "y": 7,
      "z": -2,
      "name": "Empty",
      "level": 0
    },
    {
      "x": 6,
      "y": 8,
      "z": -2,
      "name": "Empty",
      "level": 0
    },
    {
      "x": 6,
      "y": 9,
      "z": -2,
      "name": "Empty",
      "level": 0
    },
    {
      "x": 6,
      "y": 3,
      "z": 0,
      "name": "Empty",
      "level": 0
    },
    {
      "x": 6,
      "y": 4,
      "z": 0,
      "name": "Empty",
      "level": 0
    },
    {
      "x": 6,
      "y": 5,
      "z": 0,
      "name": "Empty",
      "level": 0
    },
    {
      "x": 6,
      "y": 6,
      "z": 0,
      "name": "Empty",
      "level": 0
    },
    {
      "x": 6,
      "y": 7,
      "z": 0,
      "name": "Empty",
      "level": 0
    },
    {
      "x": 6,
      "y": 5,
      "z": 2,
      "name": "Empty",
      "level": 0
    },
    {
      "x": 6,
      "y": 6,
      "z": 2,
      "name": "Empty",
      "level": 0
    },
    {
      "x": 6,
      "y": 7,
      "z": 2,
      "name": "Empty",
      "level": 0
    },
    {
      "x": 6,
      "y": 8,
      "z": 2,
      "name": "Empty",
      "level": 0
    },
    {
      "x": 6,
      "y": 9,
      "z": 2,
      "name": "Empty",
      "level": 0
    },
    {
      "x": 6,
      "y": 5,
      "z": 4,
      "name": "Empty",
      "level": 0
    },
    {
      "x": 6,
      "y": 6,
      "z": 4,
      "name": "Empty",
      "level": 0
    },
    {
      "x": 6,
      "y": 7,
      "z": 4,
      "name": "Empty",
      "level": 0
    },
    {
      "x": 6,
      "y": 8,
      "z": 4,
      "name": "Empty",
      "level": 0
    },
    {
      "x": 6,
      "y": 9,
      "z": 4,
      "name": "Empty",
      "level": 0
    },
    {
      "x": 7,
      "y": 6,
      "z": 0,
      "name": "Empty",
      "level": 0
    },
    {
      "x": 7,
      "y": 7,
      "z": 0,
      "name": "Empty",
      "level": 0
    },
    {
      "x": 7,
      "y": 8,
      "z": 0,
      "name": "Empty",
      "level": 0
    },
    {
      "x": 7,
      "y": 9,
      "z": 0,
      "name": "Empty",
      "level": 0
    },
    {
      "x": 7,
      "y": 10,
      "z": 0,
      "name": "Empty",
      "level": 0
    }
  ]
}